Workbook
Name \\: {"994시행","SUM(994시행)","YNNNN",FALSE;"9일분기시행","SUM(9일분기시행)","YNNNN",FALSE;"이분기","SUM(이분기)","YNNNN",FALSE}
Name \\: {"994시행","SUM(994시행)","YNNNN",FALSE;"9일분기시행","SUM(9일분기시행)","YNNNN",FALSE;"이분기","SUM(이분기)","YNNNN",FALSE}
Name \\: {"994시행","SUM(994시행)","YNNNN",FALSE;"9일분기시행","SUM(9일분기시행)","YNNNN",FALSE;"이분기","SUM(이분기)","YNNNN",FALSE}
Name \\: {"994시행","SUM(994시행)","YNNNN",FALSE;"9일분기시행","SUM(9일분기시행)","YNNNN",FALSE;"이분기","SUM(이분기)","YNNNN",FALSE}
Name \\: {"994시행","SUM(994시행)","YNNNN",FALSE;"9일분기시행","SUM(9일분기시행)","YNNNN",FALSE;"이분기","SUM(이분기)","YNNNN",FALSE}
Name \\: {"994시행","SUM(994시행)","YNNNN",FALSE;"9일분기시행","SUM(9일분기시행)","YNNNN",FALSE;"이분기","SUM(이분기)","YNNNN",FALSE}
Name \\: {"994시행","SUM(994시행)","YNNNN",FALSE;"9일분기시행","SUM(9일분기시행)","YNNNN",FALSE;"이분기","SUM(이분기)","YNNNN",FALSE}
Name \\: {"994시행","SUM(994시행)","YNNNN",FALSE;"9일분기시행","SUM(9일분기시행)","YNNNN",FALSE;"이분기","SUM(이분기)","YNNNN",FALSE}
Name \\: {"994시행","SUM(994시행)","YNNNN",FALSE;"9일분기시행","SUM(9일분기시행)","YNNNN",FALSE;"이분기","SUM(이분기)","YNNNN",FALSE}
Name \\: {"994시행","SUM(994시행)","YNNNN",FALSE;"9일분기시행","SUM(9일분기시행)","YNNNN",FALSE;"이분기","SUM(이분기)","YNNNN",FALSE}
Name \\: {"994시행","SUM(994시행)","YNNNN",FALSE;"9일분기시행","SUM(9일분기시행)","YNNNN",FALSE;"이분기","SUM(이분기)","YNNNN",FALSE}
Name \\: {"994시행","SUM(994시행)","YNNNN",FALSE;"9일분기시행","SUM(9일분기시행)","YNNNN",FALSE;"이분기","SUM(이분기)","YNNNN",FALSE}
Name \\: {"994시행","SUM(994시행)","YNNNN",FALSE;"9일분기시행","SUM(9일분기시행)","YNNNN",FALSE;"이분기","SUM(이분기)","YNNNN",FALSE}
Name \\: {"994시행","SUM(994시행)","YNNNN",FALSE;"9일분기시행","SUM(9일분기시행)","YNNNN",FALSE;"이분기","SUM(이분기)","YNNNN",FALSE}
Name \\: {"994시행","SUM(994시행)","YNNNN",FALSE;"9일분기시행","SUM(9일분기시행)","YNNNN",FALSE;"이분기","SUM(이분기)","YNNNN",FALSE}
Name \\: {"994시행","SUM(994시행)","YNNNN",FALSE;"9일분기시행","SUM(9일분기시행)","YNNNN",FALSE;"이분기","SUM(이분기)","YNNNN",FALSE}
Name \a: #N/A
Name \AA: #N/A
Name \b: #N/A
Name \c: #N/A
Name \d: #N/A
Name \e: #N/A
Name \f: #N/A
Name \g: #N/A
Name \h: #N/A
Name \i: #N/A
Name \j: #N/A
Name \k: #N/A
Name \l: #N/A
Name \m: #REF!
Name \m: #REF!
Name \m: #REF!
Name \m: #REF!
Name \m: #REF!
Name \m: #REF!
Name \m: #REF!
Name \m: #REF!
Name \m: #REF!
Name \m: #REF!
Name \m: #REF!
Name \m: #REF!
Name \m: #REF!
Name \m: #REF!
Name \m: #REF!
Name \n: #REF!
Name \n: #REF!
Name \n: #REF!
Name \n: #REF!
Name \n: #REF!
Name \n: #REF!
Name \n: #REF!
Name \n: #REF!
Name \n: #REF!
Name \n: #REF!
Name \n: #REF!
Name \n: #REF!
Name \n: #REF!
Name \n: #REF!
Name \n: #REF!
Name \o: #REF!

Sheet SUM
B2: 1.매출 현황
B19: ○ 매출/ 비용/ 영업이익 현황 | L19: (단위. 백만원)
B20: 구분 | G20: 2023 | H20: 2024 | I20: 2025 | J20: 2026 | K20: 비고 | M20: 비 고 | N20: 사업자료 | R20: 경쟁력 확보
N21: 1차자료 | O21: 비율 | P21: 최종자료 | Q21: 비율 | R21: 트랜스 포머 | S21: 비율 | T21: 2025년 | U21: 2026년
B22: 전체 현황 | E22: 매출(백만원) | G22: =+#REF! -> #REF! | H22: =+#REF! -> #REF! | I22: =+#REF! -> #REF! | J22: =+#REF! -> #REF! | M22: 매출(백만원) | N22: 7.0346707e+10 | P22: 8.3195031e+10 | Q22: =P22/N22 -> 1.1826429 | R22: =H22 -> #REF! | S22: =R22/P22 -> #REF! | T22: 91380 | U22: 102993 | V22: 기존
B23: 전체 현황 | E23: 비용 (백만원) | G23: =+SUM(G24:G27) -> #REF! | H23: =+SUM(H24:H27) -> #REF! | I23: =+SUM(I24:I27) -> #REF! | J23: =+SUM(J24:J27) -> #REF! | M23: 매출(생산액) | N23: 7.0346707e+10 | P23: 8.3195031e+10 | R23: =#REF! -> #REF! | T23: 110142 | U23: 138463 | V23: 트랜스 포머 2차
B24: 전체 현황 | E24: Ⅰ.원재료비 | G24: =+#REF! -> #REF! | H24: =+#REF! -> #REF! | I24: =+#REF! -> #REF! | J24: =+#REF! -> #REF! | M24: 비용 (백만원) | N24: =SUM(N25:N28) -> 6.3267335e+10 | O24: =N24/N22 -> 0.89936456 | P24: =SUM(P25:P28) -> 7.3792993e+10 | Q24: =P24/P22 -> 0.88698799 | R24: =(H24+H25+H26+H27) -> #REF! | S24: =R24/R22 -> #REF! | T24: =I22/1000000 -> #REF! | U24: =J22/1000000 -> #REF! | V24: 트랜스 포머 3차
B25: 전체 현황 | E25: Ⅱ. 노무비 | G25: =+#REF! -> #REF! | H25: =+#REF! -> #REF! | I25: =+#REF! -> #REF! | J25: =+#REF! -> #REF! | M25: Ⅰ.원재료비 | N25: 4.8212846e+10 | O25: =N25/N22 -> 0.68536039 | P25: 5.6659209e+10 | Q25: =P25/P22 -> 0.68104078 | R25: =H24 -> #REF! | S25: =R25/R22 -> #REF! | T25: =T24/T22 -> #REF! | U25: =U24/U22 -> #REF!
B26: 전체 현황 | E26: Ⅲ. 경비 | G26: =+#REF! -> #REF! | H26: =+#REF! -> #REF! | I26: =+#REF! -> #REF! | J26: =+#REF! -> #REF! | M26: Ⅱ. 노무비 | N26: 3068330760 | O26: =N26/N22 -> 0.043617262 | P26: 3696496650 | Q26: =P26/P22 -> 0.0444317 | R26: =H25 -> #REF! | S26: =R26/R22 -> #REF! | T26: (조립비 2.7%)
B27: 전체 현황 | E27: Ⅳ. 판매비와 관리비 | G27: =+#REF! -> #REF! | H27: =+#REF! -> #REF! | I27: =+#REF! -> #REF! | J27: =+#REF! -> #REF! | M27: Ⅲ. 경비 | N27: 3.8693614e+09 | O27: =N27/N22 -> 0.055004158 | P27: 4.0522813e+09 | Q27: =P27/P22 -> 0.048708213 | R27: =H26 -> #REF! | S27: =R27/R22 -> #REF!
B28: 전체 현황 | E28: 영업이익 | G28: =+#REF! -> #REF! | H28: =+#REF! -> #REF! | I28: =+#REF! -> #REF! | J28: =+#REF! -> #REF! | M28: Ⅳ. 판매비와 관리비 | N28: 8.1167966e+09 | O28: =N28/N22 -> 0.11538275 | P28: 9.3850068e+09 | Q28: =P28/P22 -> 0.1128073 | R28: =H27 -> #REF! | S28: =R28/R22 -> #REF!
G29: =+G28/G22 -> #REF! | H29: =+H28/H22 -> #REF! | I29: =+I28/I22 -> #REF! | J29: =+J28/J22 -> #REF! | M29: 영업이익 | N29: 7.0793722e+09 | O29: =N29/N22 -> 0.10063544 | P29: 9.4020373e+09 | Q29: =P29/P22 -> 0.11301201 | R29: =R22-R24 -> #REF! | S29: =R29/R22 -> #REF!
B32: 2. 비용 현황
L56: (단위. 백만원)
E57: 구분 | G57: 2023 | H57: 2024 | I57: DIFF | J57: % | L57: 비고
B59: 전체 현황 | E59: Ⅰ.원재료비 | G59: =+G24 -> #REF! | H59: =+H24 -> #REF! | I59: =+(H59-G59) -> #REF! | J59: =+I59/G59 -> #REF!
B60: 전체 현황 | E60: Ⅱ. 노무비 | G60: =+G25 -> #REF! | H60: =+H25 -> #REF! | I60: =+(H60-G60) -> #REF! | J60: =+I60/G60 -> #REF!
B61: 전체 현황 | E61: Ⅲ. 경비 | G61: =+G26 -> #REF! | H61: =+H26 -> #REF! | I61: =+(H61-G61) -> #REF! | J61: =+I61/G61 -> #REF!
B62: 전체 현황 | E62: Ⅳ. 판매비와 관리비 | G62: =+G27 -> #REF! | H62: =+H27 -> #REF! | I62: =+(H62-G62) -> #REF! | J62: =+I62/G62 -> #REF!
B63: 전체 현황 | E63: 비용 (백만원) | G63: =SUM(G59:G62) -> #REF! | H63: =SUM(H59:H62) -> #REF! | I63: =SUM(I59:I62) -> #REF! | J63: =+I63/G63 -> #REF!
B64: 전체 현황 | E64: 비용/ 매출 (%) | G64: =+G63/G22 -> #REF! | H64: =+H63/H22 -> #REF!

Sheet 표준대비 증감
B1: 손익 증감 요인 | D1: =+E1-1 -> 6 | E1: 7 | F1: =+IF(E1=12,1,E1+1) -> 8 | G1: =+F1+1 -> 9 | H1: =+G1+1 -> 10
D2: =+D1*1.12 -> 6.72 | E2: =+E1*1.12 -> 7.84 | F2: =+F1*1.12 -> 8.96 | G2: =+G1*1.12 -> 10.08 | H2: =+H1*1.12 -> 11.2
B3: =+"1.1. "&D1&"월 사업목표대비 실적 - 금액기준" -> 1.1. 6월 사업목표대비 실적 - 금액기준
B4: 구분 | C4: 매출(천원) | D4: 생산(천원) | E4: 원재료비(천원) | F4: 노무비(천원) | G4: 경비(천원) | H4: 판매관리비(천원)
B5: 사업목표 | C5: =+INDEX('2026-사업계획-PL'!$T:$AQ,68,MATCH($D$1,'2026-사업계획-PL'!$T$1:$AQ$1,0)) -> 9.5181202e+09 | D5: =+INDEX('2026-사업계획-MC'!$T:$AQ,49,MATCH($D$1,'2026-사업계획-MC'!$T$1:$AQ$1,0)) -> 9.5181202e+09 | E5: =+INDEX('2026-사업계획-MC'!$T:$AQ,50,MATCH($D$1,'2026-사업계획-MC'!$T$1:$AQ$1,0)) -> 6.535768e+09 | F5: =+INDEX('2026-사업계획-MC'!$T:$AQ,55,MATCH($D$1,'2026-사업계획-MC'!$T$1:$AQ$1,0)) -> 4.1832178e+08 | G5: =+INDEX('2026-사업계획-MC'!$T:$AQ,61,MATCH($D$1,'2026-사업계획-MC'!$T$1:$AQ$1,0)) -> 5.3978074e+08 | H5: =+INDEX('2026-사업계획-PL'!$T:$AQ,90,MATCH($D$1,'2026-사업계획-PL'!$T$1:$AQ$1,0)) -> 1.1499958e+09
B6: 운영목표 | C6: =+INDEX('2026-운영계획 PL'!$T:$AQ,68,MATCH($D$1,'2026-운영계획 PL'!$T$1:$AQ$1,0)) -> 9.5700172e+09 | D6: =+INDEX('2026-운영계획-MC'!$T:$AQ,49,MATCH($D$1,'2026-운영계획-MC'!$T$1:$AQ$1,0)) -> 9.0912914e+09 | E6: =+INDEX('2026-운영계획-MC'!$T:$AQ,50,MATCH($D$1,'2026-운영계획-MC'!$T$1:$AQ$1,0)) -> 6.3238281e+09 | F6: =+INDEX('2026-운영계획-MC'!$T:$AQ,55,MATCH($D$1,'2026-운영계획-MC'!$T$1:$AQ$1,0)) -> 4.1138161e+08 | G6: =+INDEX('2026-운영계획-MC'!$T:$AQ,61,MATCH($D$1,'2026-운영계획-MC'!$T$1:$AQ$1,0)) -> 5.3092971e+08 | H6: =+INDEX('2026-운영계획 PL'!$T:$AQ,90,MATCH($D$1,'2026-운영계획 PL'!$T$1:$AQ$1,0)) -> 1.1572182e+09
B7: 실적 | C7: =+INDEX('2026-실적 PL'!$O:$AL,68,MATCH($D$1,'2026-실적 PL'!$O$1:$AL$1,0)) -> 0 | D7: =+INDEX('2026-실적-MC'!$T:$AQ,49,MATCH($D$1,'2026-실적-MC'!$T$1:$AQ$1,0)) -> 0 | E7: =+INDEX('2026-실적-MC'!$T:$AQ,50,MATCH($D$1,'2026-실적-MC'!$T$1:$AQ$1,0)) -> 0 | F7: =+INDEX('2026-실적-MC'!$T:$AQ,55,MATCH($D$1,'2026-실적-MC'!$T$1:$AQ$1,0)) -> 0 | G7: =+INDEX('2026-실적-MC'!$T:$AQ,61,MATCH($D$1,'2026-실적-MC'!$T$1:$AQ$1,0)) -> 0 | H7: =+INDEX('2026-실적 PL'!$T:$AQ,90,MATCH($D$1,'2026-실적 PL'!$T$1:$AQ$1,0)) -> 0
C8: =C7/C6 -> 0 | D8: =D7/D6 -> 0
B9: =+"1.2. "&D1&"월 사업목표대비 실적 - 비율기준" -> 1.2. 6월 사업목표대비 실적 - 비율기준
B10: 구분 | C10: 달성율(%) | D10: 영업이익(%) | E10: 원재료비(%) | F10: 노무비(%) | G10: 경비(%) | H10: 판매관리비(%)
B11: 사업목표 | D11: =+INDEX('2026-사업계획-PL'!$T:$AQ,121,MATCH($D$2,'2026-사업계획-PL'!$T$1:$AQ$1,0)) -> 0.091851529 | E11: =+INDEX('2026-사업계획-MC'!$T:$AQ,50,MATCH($D$2,'2026-사업계획-MC'!$T$1:$AQ$1,0)) -> 0.68666584 | F11: =+INDEX('2026-사업계획-MC'!$T:$AQ,55,MATCH($D$2,'2026-사업계획-MC'!$T$1:$AQ$1,0)) -> 0.043950042 | G11: =+INDEX('2026-사업계획-MC'!$T:$AQ,61,MATCH($D$2,'2026-사업계획-MC'!$T$1:$AQ$1,0)) -> 0.056710855 | H11: =+INDEX('2026-사업계획-PL'!$T:$AQ,90,MATCH($D$2,'2026-사업계획-PL'!$T$1:$AQ$1,0)) -> 0.12082173 | I11: =+G11+F11+E11 -> 0.78732674
B12: 운영목표 | C12: =C6/C5 -> 1.0054524 | D12: =+INDEX('2026-운영계획 PL'!$T:$AQ,121,MATCH($D$2,'2026-운영계획 PL'!$T$1:$AQ$1,0)) -> 0.11981792 | E12: =+INDEX('2026-운영계획-MC'!$T:$AQ,50,MATCH($D$2,'2026-운영계획-MC'!$T$1:$AQ$1,0)) -> 0.69559184 | F12: =+INDEX('2026-운영계획-MC'!$T:$AQ,55,MATCH($D$2,'2026-운영계획-MC'!$T$1:$AQ$1,0)) -> 0.045250074 | G12: =+INDEX('2026-운영계획-MC'!$T:$AQ,61,MATCH($D$2,'2026-운영계획-MC'!$T$1:$AQ$1,0)) -> 0.058399812 | H12: =+INDEX('2026-운영계획 PL'!$T:$AQ,90,MATCH($D$2,'2026-운영계획 PL'!$T$1:$AQ$1,0)) -> 0.12092122 | I12: =+G12+F12+E12 -> 0.79924172
B13: 실 적 | C13: =C7/C5 -> 0 | D13: =+INDEX('2026-실적 PL'!$T:$AQ,121,MATCH($D$2,'2026-실적 PL'!$T$1:$AQ$1,0)) -> 0 | E13: =+INDEX('2026-실적-MC'!$T:$AQ,50,MATCH($D$2,'2026-실적-MC'!$T$1:$AQ$1,0)) -> 0 | F13: =+INDEX('2026-실적-MC'!$T:$AQ,55,MATCH($D$2,'2026-실적-MC'!$T$1:$AQ$1,0)) -> 0 | G13: =+INDEX('2026-실적-MC'!$T:$AQ,61,MATCH($D$2,'2026-실적-MC'!$T$1:$AQ$1,0)) -> 0 | H13: =+INDEX('2026-실적 PL'!$T:$AQ,90,MATCH($D$2,'2026-실적 PL'!$T$1:$AQ$1,0)) -> 0 | I13: =+G13+F13+E13 -> 0
D14: =D13-D12 -> -0.11981792 | E14: =E13-E12 -> -0.69559184 | F14: =F13-F12 -> -0.045250074 | G14: =G13-G12 -> -0.058399812 | H14: =H13-H12 -> -0.12092122 | I14: =+G14+F14+E14 -> -0.79924172
B15: =+"2.1. "&E1&"월 사업목표대비 실적 - 금액기준" -> 2.1. 7월 사업목표대비 실적 - 금액기준
B16: 구분 | C16: 매출(천원) | D16: 생산(천원) | E16: 원재료비(천원) | F16: 노무비(천원) | G16: 경비(천원) | H16: 판매관리비(천원)
B17: 사업목표 | C17: =+INDEX('2026-사업계획-PL'!$T:$AQ,68,MATCH($E$1,'2026-사업계획-PL'!$T$1:$AQ$1,0)) -> 8.7172907e+09 | D17: =+INDEX('2026-사업계획-MC'!$T:$AQ,49,MATCH($E$1,'2026-사업계획-MC'!$T$1:$AQ$1,0)) -> 8.7172907e+09 | E17: =+INDEX('2026-사업계획-MC'!$T:$AQ,50,MATCH($E$1,'2026-사업계획-MC'!$T$1:$AQ$1,0)) -> 6.03839e+09 | F17: =+INDEX('2026-사업계획-MC'!$T:$AQ,55,MATCH($E$1,'2026-사업계획-MC'!$T$1:$AQ$1,0)) -> 3.7802426e+08 | G17: =+INDEX('2026-사업계획-MC'!$T:$AQ,61,MATCH($E$1,'2026-사업계획-MC'!$T$1:$AQ$1,0)) -> 5.1744752e+08 | H17: =+INDEX('2026-사업계획-PL'!$T:$AQ,90,MATCH($E$1,'2026-사업계획-PL'!$T$1:$AQ$1,0)) -> 1.0600084e+09
B18: 운영목표 | C18: =+INDEX('2026-운영계획 PL'!$T:$AQ,68,MATCH($E$1,'2026-운영계획 PL'!$T$1:$AQ$1,0)) -> 1.1293306e+10 | D18: =+INDEX('2026-운영계획-MC'!$T:$AQ,49,MATCH($E$1,'2026-운영계획-MC'!$T$1:$AQ$1,0)) -> 1.0639273e+10 | E18: =+INDEX('2026-운영계획-MC'!$T:$AQ,50,MATCH($E$1,'2026-운영계획-MC'!$T$1:$AQ$1,0)) -> 7.6603444e+09 | F18: =+INDEX('2026-운영계획-MC'!$T:$AQ,55,MATCH($E$1,'2026-운영계획-MC'!$T$1:$AQ$1,0)) -> 5.0916036e+08 | G18: =+INDEX('2026-운영계획-MC'!$T:$AQ,61,MATCH($E$1,'2026-운영계획-MC'!$T$1:$AQ$1,0)) -> 5.655093e+08 | H18: =+INDEX('2026-운영계획 PL'!$T:$AQ,90,MATCH($E$1,'2026-운영계획 PL'!$T$1:$AQ$1,0)) -> 1.2730862e+09
B19: 실적 | C19: =+INDEX('2026-실적 PL'!$O:$AL,68,MATCH($E$1,'2026-실적 PL'!$O$1:$AL$1,0)) -> 0 | D19: =+INDEX('2026-실적-MC'!$T:$AQ,49,MATCH($E$1,'2026-실적-MC'!$T$1:$AQ$1,0)) -> 0 | E19: =+INDEX('2026-실적-MC'!$T:$AQ,50,MATCH($E$1,'2026-실적-MC'!$T$1:$AQ$1,0)) -> 0 | F19: =+INDEX('2026-실적-MC'!$T:$AQ,55,MATCH($E$1,'2026-실적-MC'!$T$1:$AQ$1,0)) -> 0 | G19: =+INDEX('2026-실적-MC'!$T:$AQ,61,MATCH($E$1,'2026-실적-MC'!$T$1:$AQ$1,0)) -> 0 | H19: =+INDEX('2026-실적 PL'!$T:$AQ,90,MATCH($E$1,'2026-실적 PL'!$T$1:$AQ$1,0)) -> 0
C20: =C19/C18 -> 0 | D20: =D19/D18 -> 0
B21: =+"2.2. "&E1&"월 사업목표대비 실적 - 비율기준" -> 2.2. 7월 사업목표대비 실적 - 비율기준
B22: 구분 | C22: 달성율(%) | D22: 영업이익(%) | E22: 원재료비(%) | F22: 노무비(%) | G22: 경비(%) | H22: 판매관리비(%)
B23: 사업목표 | D23: =+INDEX('2026-사업계획-PL'!$T:$AQ,121,MATCH($E$2,'2026-사업계획-PL'!$T$1:$AQ$1,0)) -> 0.082986851 | E23: =+INDEX('2026-사업계획-MC'!$T:$AQ,50,MATCH($E$2,'2026-사업계획-MC'!$T$1:$AQ$1,0)) -> 0.69269114 | F23: =+INDEX('2026-사업계획-MC'!$T:$AQ,55,MATCH($E$2,'2026-사업계획-MC'!$T$1:$AQ$1,0)) -> 0.04336488 | G23: =+INDEX('2026-사업계획-MC'!$T:$AQ,61,MATCH($E$2,'2026-사업계획-MC'!$T$1:$AQ$1,0)) -> 0.059358755 | H23: =+INDEX('2026-사업계획-PL'!$T:$AQ,90,MATCH($E$2,'2026-사업계획-PL'!$T$1:$AQ$1,0)) -> 0.12159838 | I23: =+G23+F23+E23 -> 0.79541477
B24: 운영목표 | C24: =C18/C17 -> 1.2955064 | D24: =+INDEX('2026-운영계획 PL'!$T:$AQ,121,MATCH($E$2,'2026-운영계획 PL'!$T$1:$AQ$1,0)) -> 0.11380246 | E24: =+INDEX('2026-운영계획-MC'!$T:$AQ,50,MATCH($E$2,'2026-운영계획-MC'!$T$1:$AQ$1,0)) -> 0.72000637 | F24: =+INDEX('2026-운영계획-MC'!$T:$AQ,55,MATCH($E$2,'2026-운영계획-MC'!$T$1:$AQ$1,0)) -> 0.047856687 | G24: =+INDEX('2026-운영계획-MC'!$T:$AQ,61,MATCH($E$2,'2026-운영계획-MC'!$T$1:$AQ$1,0)) -> 0.053153002 | H24: =+INDEX('2026-운영계획 PL'!$T:$AQ,90,MATCH($E$2,'2026-운영계획 PL'!$T$1:$AQ$1,0)) -> 0.11272927 | I24: =+G24+F24+E24 -> 0.82101606
B25: 실 적 | C25: =C19/C17 -> 0 | D25: =+INDEX('2026-실적 PL'!$T:$AQ,121,MATCH($E$2,'2026-실적 PL'!$T$1:$AQ$1,0)) -> 0 | E25: =+INDEX('2026-실적-MC'!$T:$AQ,50,MATCH($E$2,'2026-실적-MC'!$T$1:$AQ$1,0)) -> 0 | F25: =+INDEX('2026-실적-MC'!$T:$AQ,55,MATCH($E$2,'2026-실적-MC'!$T$1:$AQ$1,0)) -> 0 | G25: =+INDEX('2026-실적-MC'!$T:$AQ,61,MATCH($E$2,'2026-실적-MC'!$T$1:$AQ$1,0)) -> 0 | H25: =+INDEX('2026-실적 PL'!$T:$AQ,90,MATCH($E$2,'2026-실적 PL'!$T$1:$AQ$1,0)) -> 0 | I25: =+G25+F25+E25 -> 0
D26: =D25-D24 -> -0.11380246 | E26: =E25-E24 -> -0.72000637 | F26: =F25-F24 -> -0.047856687 | G26: =G25-G24 -> -0.053153002 | H26: =H25-H24 -> -0.11272927 | I26: =+G26+F26+E26 -> -0.82101606
B27: =+"3.1. "&F1&"월 사업목표대비 실적 - 금액기준" -> 3.1. 8월 사업목표대비 실적 - 금액기준
B28: 구분 | C28: 매출(천원) | D28: 생산(천원) | E28: 원재료비(천원) | F28: 노무비(천원) | G28: 경비(천원) | H28: 판매관리비(천원)
B29: 사업목표 | C29: =+INDEX('2026-사업계획-PL'!$T:$AQ,68,MATCH($F$1,'2026-사업계획-PL'!$T$1:$AQ$1,0)) -> 9.6669222e+09 | D29: =+INDEX('2026-사업계획-MC'!$T:$AQ,49,MATCH($F$1,'2026-사업계획-MC'!$T$1:$AQ$1,0)) -> 9.6669222e+09 | E29: =+INDEX('2026-사업계획-MC'!$T:$AQ,50,MATCH($F$1,'2026-사업계획-MC'!$T$1:$AQ$1,0)) -> 6.8149369e+09 | F29: =+INDEX('2026-사업계획-MC'!$T:$AQ,55,MATCH($F$1,'2026-사업계획-MC'!$T$1:$AQ$1,0)) -> 4.2490661e+08 | G29: =+INDEX('2026-사업계획-MC'!$T:$AQ,61,MATCH($F$1,'2026-사업계획-MC'!$T$1:$AQ$1,0)) -> 5.4324523e+08 | H29: =+INDEX('2026-사업계획-PL'!$T:$AQ,90,MATCH($F$1,'2026-사업계획-PL'!$T$1:$AQ$1,0)) -> 1.1531247e+09
B30: 운영목표 | C30: =+INDEX('2026-운영계획 PL'!$T:$AQ,68,MATCH($F$1,'2026-운영계획 PL'!$T$1:$AQ$1,0)) -> 1.0222028e+10 | D30: =+INDEX('2026-운영계획-MC'!$T:$AQ,49,MATCH($F$1,'2026-운영계획-MC'!$T$1:$AQ$1,0)) -> 1.0222028e+10 | E30: =+INDEX('2026-운영계획-MC'!$T:$AQ,50,MATCH($F$1,'2026-운영계획-MC'!$T$1:$AQ$1,0)) -> 7.707848e+09 | F30: =+INDEX('2026-운영계획-MC'!$T:$AQ,55,MATCH($F$1,'2026-운영계획-MC'!$T$1:$AQ$1,0)) -> 5.0019176e+08 | G30: =+INDEX('2026-운영계획-MC'!$T:$AQ,61,MATCH($F$1,'2026-운영계획-MC'!$T$1:$AQ$1,0)) -> 5.7058492e+08 | H30: =+INDEX('2026-운영계획 PL'!$T:$AQ,90,MATCH($F$1,'2026-운영계획 PL'!$T$1:$AQ$1,0)) -> 1.1907592e+09
B31: 실적 | C31: =+INDEX('2026-실적 PL'!$T:$AQ,68,MATCH($F$1,'2026-실적 PL'!$T$1:$AQ$1,0)) -> 0 | D31: =+INDEX('2026-실적-MC'!$T:$AQ,49,MATCH($F$1,'2026-실적-MC'!$T$1:$AQ$1,0)) -> 0 | E31: =+INDEX('2026-실적-MC'!$T:$AQ,50,MATCH($F$1,'2026-실적-MC'!$T$1:$AQ$1,0)) -> 0 | F31: =+INDEX('2026-실적-MC'!$T:$AQ,55,MATCH($F$1,'2026-실적-MC'!$T$1:$AQ$1,0)) -> 0 | G31: =+INDEX('2026-실적-MC'!$T:$AQ,61,MATCH($F$1,'2026-실적-MC'!$T$1:$AQ$1,0)) -> 0 | H31: =+INDEX('2026-실적 PL'!$T:$AQ,90,MATCH($F$1,'2026-실적 PL'!$T$1:$AQ$1,0)) -> 0
B33: =+"3.2. "&F1&"월 사업목표대비 실적 - 비율기준" -> 3.2. 8월 사업목표대비 실적 - 비율기준
B34: 구분 | C34: 달성율(%) | D34: 영업이익(%) | E34: 원재료비(%) | F34: 노무비(%) | G34: 경비(%) | H34: 판매관리비(%)
B35: 사업목표 | D35: =+INDEX('2026-사업계획-PL'!$T:$AQ,121,MATCH($F$2,'2026-사업계획-PL'!$T$1:$AQ$1,0)) -> 0.07558856 | E35: =+INDEX('2026-사업계획-MC'!$T:$AQ,50,MATCH($F$2,'2026-사업계획-MC'!$T$1:$AQ$1,0)) -> 0.70497484 | F35: =+INDEX('2026-사업계획-MC'!$T:$AQ,55,MATCH($F$2,'2026-사업계획-MC'!$T$1:$AQ$1,0)) -> 0.043954694 | G35: =+INDEX('2026-사업계획-MC'!$T:$AQ,61,MATCH($F$2,'2026-사업계획-MC'!$T$1:$AQ$1,0)) -> 0.056196296 | H35: =+INDEX('2026-사업계획-PL'!$T:$AQ,90,MATCH($F$2,'2026-사업계획-PL'!$T$1:$AQ$1,0)) -> 0.11928561 | I35: =+G35+F35+E35 -> 0.80512583
B36: 운영목표 | C36: =C30/C29 -> 1.0574232 | D36: =+INDEX('2026-운영계획 PL'!$T:$AQ,121,MATCH($F$2,'2026-운영계획 PL'!$T$1:$AQ$1,0)) -> 0.02471568 | E36: =+INDEX('2026-운영계획-MC'!$T:$AQ,50,MATCH($F$2,'2026-운영계획-MC'!$T$1:$AQ$1,0)) -> 0.75404291 | F36: =+INDEX('2026-운영계획-MC'!$T:$AQ,55,MATCH($F$2,'2026-운영계획-MC'!$T$1:$AQ$1,0)) -> 0.048932731 | G36: =+INDEX('2026-운영계획-MC'!$T:$AQ,61,MATCH($F$2,'2026-운영계획-MC'!$T$1:$AQ$1,0)) -> 0.055819148 | H36: =+INDEX('2026-운영계획 PL'!$T:$AQ,90,MATCH($F$2,'2026-운영계획 PL'!$T$1:$AQ$1,0)) -> 0.11648953 | I36: =+G36+F36+E36 -> 0.85879479
B37: 사업목표 대비 | D37: =D36-D35 -> -0.05087288 | E37: =E36-E35 -> 0.049068076 | F37: =F36-F35 -> 0.0049780366 | G37: =G36-G35 -> -0.00037714796 | H37: =H36-H35 -> -0.0027960842 | I37: =+G37+F37+E37 -> 0.053668964
D38: =D37-D36 -> -0.07558856 | E38: =E37-E36 -> -0.70497484 | F38: =F37-F36 -> -0.043954694 | G38: =G37-G36 -> -0.056196296 | H38: =H37-H36 -> -0.11928561 | I38: =+G38+F38+E38 -> -0.80512583
B39: =+"3.1. "&G1&"월 사업목표대비 실적 - 금액기준" -> 3.1. 9월 사업목표대비 실적 - 금액기준
B40: 구분 | C40: 매출(천원) | D40: 생산(천원) | E40: 원재료비(천원) | F40: 노무비(천원) | G40: 경비(천원) | H40: 판매관리비(천원)
B41: 사업목표 | C41: =+INDEX('2025-사업계획-PL'!$O:$AL,68,MATCH($G$1,'2025-사업계획-PL'!$O$1:$AL$1,0)) -> 9.7258784e+09 | D41: =+INDEX('2025-사업계획-MC'!$O:$AL,49,MATCH($G$1,'2025-사업계획-MC'!$O$1:$AL$1,0)) -> 9.7258784e+09 | E41: =+INDEX('2025-사업계획-MC'!$O:$AL,50,MATCH($G$1,'2025-사업계획-MC'!$O$1:$AL$1,0)) -> 6.837891e+09 | F41: =+INDEX('2025-사업계획-MC'!$O:$AL,55,MATCH($G$1,'2025-사업계획-MC'!$O$1:$AL$1,0)) -> 4.5974199e+08 | G41: =+INDEX('2025-사업계획-MC'!$O:$AL,61,MATCH($G$1,'2025-사업계획-MC'!$O$1:$AL$1,0)) -> 4.9337472e+08 | H41: =+INDEX('2025-사업계획-PL'!$O:$AL,90,MATCH($G$1,'2025-사업계획-PL'!$O$1:$AL$1,0)) -> 1.2190603e+09
...

Sheet 실적-PL 2026
B1: =+J1&"월 목표vs실적- 베트남" -> 7월 목표vs실적- 베트남 | I1: 월 | J1: 7
I2: 전월 | J2: =+IF(J1-1=0,12,J1-1) -> 6
B3: 손익계산서(현지통화) | M3: (단위: VND )
B4: 계정과목 | C4: 전년동월 | E4: 전월 | G4: 사업목표 | I4: 운영목표 | K4: 실적 | M4: 달성율 | P4: 차이
P5: 사업목표 VS 실적 | R5: 운영목표 VS 실적 | T5: 요약 내용
C6: 금액 | D6: 비율 | E6: 금액 | F6: 비율 | G6: 금액 | H6: 비율 | I6: 금액 | J6: 비율 | K6: 금액 | L6: 비율 | M6: 사업목표 대비 | N6: 운영목표 대비 | P6: 금액 | Q6: 비율 | R6: 금액 | S6: 비율
B7: Ⅰ. 매출액 | C7: =+INDEX(#REF!,ROW('실적-PL 2026'!$B7),MATCH('실적-PL 2026'!$J$1,#REF!,0)) -> #REF! | D7: =+D8+D11+D15 -> #REF! | E7: =+INDEX('2026-실적 PL'!$T:$AQ,ROW($B7),MATCH($J$2,'2026-실적 PL'!$T$1:$AQ$1,0)) -> 0 | F7: =+IFERROR(F8+F11,0) -> 0 | G7: =+INDEX('2026-사업계획-PL'!$T:$AQ,ROW($B7),MATCH($J$1,'2026-사업계획-PL'!$T$1:$AQ$1,0)) -> 1.5849619e+11 | H7: =+H8+H11+H15 -> 1 | I7: =+INDEX('2026-운영계획 PL'!$T:$AQ,ROW($B7),MATCH($J$1,'2026-운영계획 PL'!$T$1:$AQ$1,0)) -> 2.0533284e+11 | J7: 1 | K7: =+INDEX('2026-실적 PL'!$O:$AL,ROW($B7),MATCH($J$1,'2026-실적 PL'!$O$1:$AL$1,0)) -> 0 | L7: =+IFERROR(K7/$K$7,0) -> 0 | M7: =IF(G7=0,"",K7/G7) -> 0 | N7: =IF(I7=0,"",K7/I7) -> 0 | P7: =K7-G7 -> -1.5849619e+11 | Q7: =L7-H7 -> -1 | R7: =K7-I7 -> -2.0533284e+11 | S7: =L7-J7 -> -1
B8: 01.제품매출 | C8: =+INDEX(#REF!,ROW('실적-PL 2026'!$B8),MATCH('실적-PL 2026'!$J$1,#REF!,0)) -> #REF! | D8: =+D9+D10 -> #REF! | E8: =+INDEX('2026-실적 PL'!$T:$AQ,ROW($B8),MATCH($J$2,'2026-실적 PL'!$T$1:$AQ$1,0)) -> 0 | F8: =+F9+F10 -> 0 | G8: =+INDEX('2026-사업계획-PL'!$T:$AQ,ROW($B8),MATCH($J$1,'2026-사업계획-PL'!$T$1:$AQ$1,0)) -> 1.5849619e+11 | H8: =+H9+H10 -> 1 | I8: =+INDEX('2026-운영계획 PL'!$T:$AQ,ROW($B8),MATCH($J$1,'2026-운영계획 PL'!$T$1:$AQ$1,0)) -> 2.0533284e+11 | J8: =+J9+J10 -> 1 | K8: =+INDEX('2026-실적 PL'!$O:$AL,ROW($B8),MATCH($J$1,'2026-실적 PL'!$O$1:$AL$1,0)) -> 0 | L8: =+IFERROR(K8/$K$7,0) -> 0 | M8: =IF(G8=0,"",K8/G8) -> 0 | N8: =IF(I8=0,"",K8/I8) -> 0 | P8: =K8-G8 -> -1.5849619e+11 | Q8: =L8-H8 -> -1 | R8: =K8-I8 -> -2.0533284e+11 | S8: =L8-J8 -> -1
B9: (1) 국내매출 | C9: =+INDEX(#REF!,ROW('실적-PL 2026'!$B9),MATCH('실적-PL 2026'!$J$1,#REF!,0)) -> #REF! | D9: =+C9/C7 -> #REF! | E9: =+INDEX('2026-실적 PL'!$T:$AQ,ROW($B9),MATCH($J$2,'2026-실적 PL'!$T$1:$AQ$1,0)) -> 0 | F9: =+IFERROR(E9/$E$7,0) -> 0 | G9: =+INDEX('2026-사업계획-PL'!$T:$AQ,ROW($B9),MATCH($J$1,'2026-사업계획-PL'!$T$1:$AQ$1,0)) -> 1.8534935e+09 | H9: =+G9/G7 -> 0.011694246 | I9: =+INDEX('2026-운영계획 PL'!$T:$AQ,ROW($B9),MATCH($J$1,'2026-운영계획 PL'!$T$1:$AQ$1,0)) -> 2.983303e+09 | J9: =+I9/I7 -> 0.014529108 | K9: =+INDEX('2026-실적 PL'!$O:$AL,ROW($B9),MATCH($J$1,'2026-실적 PL'!$O$1:$AL$1,0)) -> 0 | L9: =+IFERROR(K9/$K$7,0) -> 0 | M9: =IF(G9=0,"",K9/G9) -> 0 | N9: =IF(I9=0,"",K9/I9) -> 0 | P9: =K9-G9 -> -1.8534935e+09 | Q9: =L9-H9 -> -0.011694246 | R9: =K9-I9 -> -2.983303e+09 | S9: =L9-J9 -> -0.014529108
B10: (2) 국외매출 (CBU) | C10: =+INDEX(#REF!,ROW('실적-PL 2026'!$B10),MATCH('실적-PL 2026'!$J$1,#REF!,0)) -> #REF! | D10: =+C10/C7 -> #REF! | E10: =+INDEX('2026-실적 PL'!$T:$AQ,ROW($B10),MATCH($J$2,'2026-실적 PL'!$T$1:$AQ$1,0)) -> 0 | F10: =+IFERROR(E10/$E$7,0) -> 0 | G10: =+INDEX('2026-사업계획-PL'!$T:$AQ,ROW($B10),MATCH($J$1,'2026-사업계획-PL'!$T$1:$AQ$1,0)) -> 1.566427e+11 | H10: =+G10/G7 -> 0.98830575 | I10: =+INDEX('2026-운영계획 PL'!$T:$AQ,ROW($B10),MATCH($J$1,'2026-운영계획 PL'!$T$1:$AQ$1,0)) -> 2.0234954e+11 | J10: =+I10/I7 -> 0.98547089 | K10: =+INDEX('2026-실적 PL'!$O:$AL,ROW($B10),MATCH($J$1,'2026-실적 PL'!$O$1:$AL$1,0)) -> 0 | L10: =+IFERROR(K10/$K$7,0) -> 0 | M10: =IF(G10=0,"",K10/G10) -> 0 | N10: =IF(I10=0,"",K10/I10) -> 0 | P10: =K10-G10 -> -1.566427e+11 | Q10: =L10-H10 -> -0.98830575 | R10: =K10-I10 -> -2.0234954e+11 | S10: =L10-J10 -> -0.98547089
B11: 02.상품매출 | C11: =+INDEX(#REF!,ROW('실적-PL 2026'!$B11),MATCH('실적-PL 2026'!$J$1,#REF!,0)) -> #REF! | D11: =IF($G$7=0,"",C11/$G$7) -> #REF! | E11: =+INDEX('2026-실적 PL'!$T:$AQ,ROW($B11),MATCH($J$2,'2026-실적 PL'!$T$1:$AQ$1,0)) -> 0 | F11: =+IFERROR(E11/$E$7,0) -> 0 | G11: =+INDEX('2026-사업계획-PL'!$T:$AQ,ROW($B11),MATCH($J$1,'2026-사업계획-PL'!$T$1:$AQ$1,0)) -> 0 | H11: =IF($G$7=0,"",G11/$G$7) -> 0 | I11: =+INDEX('2026-운영계획 PL'!$T:$AQ,ROW($B11),MATCH($J$1,'2026-운영계획 PL'!$T$1:$AQ$1,0)) -> 0 | J11: =IF($I$7=0,"",I11/$I$7) -> 0 | K11: =+INDEX('2026-실적 PL'!$O:$AL,ROW($B11),MATCH($J$1,'2026-실적 PL'!$O$1:$AL$1,0)) -> 0 | L11: =+IFERROR(K11/$K$7,0) -> 0 | M11: =IF(G11=0,"",K11/G11) | N11: =IF(I11=0,"",K11/I11) | P11: =K11-G11 -> 0 | Q11: =L11-H11 -> 0 | R11: =K11-I11 -> 0 | S11: =L11-J11 -> 0
B12: (1) 국내매출-통합구매-NET | C12: =+INDEX(#REF!,ROW('실적-PL 2026'!$B12),MATCH('실적-PL 2026'!$J$1,#REF!,0)) -> #REF! | D12: =IF($G$7=0,"",C12/$G$7) -> #REF! | E12: =+INDEX('2026-실적 PL'!$T:$AQ,ROW($B12),MATCH($J$2,'2026-실적 PL'!$T$1:$AQ$1,0)) -> 0 | F12: =+IFERROR(E12/$E$7,0) -> 0 | G12: =+INDEX('2026-사업계획-PL'!$T:$AQ,ROW($B12),MATCH($J$1,'2026-사업계획-PL'!$T$1:$AQ$1,0)) -> 0 | H12: =IF($G$7=0,"",G12/$G$7) -> 0 | I12: =+INDEX('2026-운영계획 PL'!$T:$AQ,ROW($B12),MATCH($J$1,'2026-운영계획 PL'!$T$1:$AQ$1,0)) -> 0 | J12: =IF($I$7=0,"",I12/$I$7) -> 0 | K12: =+INDEX('2026-실적 PL'!$O:$AL,ROW($B12),MATCH($J$1,'2026-실적 PL'!$O$1:$AL$1,0)) -> 0 | L12: =+IFERROR(K12/$K$7,0) -> 0 | M12: =IF(G12=0,"",K12/G12) | N12: =IF(I12=0,"",K12/I12) | P12: =K12-G12 -> 0 | Q12: =L12-H12 -> 0 | R12: =K12-I12 -> 0 | S12: =L12-J12 -> 0
B13: 국내매출-통합구매-GROSS | C13: =+INDEX(#REF!,ROW('실적-PL 2026'!$B13),MATCH('실적-PL 2026'!$J$1,#REF!,0)) -> #REF! | D13: =IF($G$7=0,"",C13/$G$7) -> #REF! | E13: =+INDEX('2026-실적 PL'!$T:$AQ,ROW($B13),MATCH($J$2,'2026-실적 PL'!$T$1:$AQ$1,0)) -> 0 | F13: =+IFERROR(E13/$E$7,0) -> 0 | G13: =+INDEX('2026-사업계획-PL'!$T:$AQ,ROW($B13),MATCH($J$1,'2026-사업계획-PL'!$T$1:$AQ$1,0)) -> 0 | H13: =IF($G$7=0,"",G13/$G$7) -> 0 | I13: =+INDEX('2026-운영계획 PL'!$T:$AQ,ROW($B13),MATCH($J$1,'2026-운영계획 PL'!$T$1:$AQ$1,0)) -> 0 | J13: =IF($I$7=0,"",I13/$I$7) -> 0 | K13: =+INDEX('2026-실적 PL'!$O:$AL,ROW($B13),MATCH($J$1,'2026-실적 PL'!$O$1:$AL$1,0)) -> 0 | L13: =+IFERROR(K13/$K$7,0) -> 0 | M13: =IF(G13=0,"",K13/G13) | N13: =IF(I13=0,"",K13/I13) | P13: =K13-G13 -> 0 | Q13: =L13-H13 -> 0 | R13: =K13-I13 -> 0 | S13: =L13-J13 -> 0
B14: (2) 국외매출 (CKD) | C14: =+INDEX(#REF!,ROW('실적-PL 2026'!$B14),MATCH('실적-PL 2026'!$J$1,#REF!,0)) -> #REF! | D14: =IF($G$7=0,"",C14/$G$7) -> #REF! | E14: =+INDEX('2026-실적 PL'!$T:$AQ,ROW($B14),MATCH($J$2,'2026-실적 PL'!$T$1:$AQ$1,0)) -> 0 | F14: =+IFERROR(E14/$E$7,0) -> 0 | G14: =+INDEX('2026-사업계획-PL'!$T:$AQ,ROW($B14),MATCH($J$1,'2026-사업계획-PL'!$T$1:$AQ$1,0)) -> 0 | H14: =IF($G$7=0,"",G14/$G$7) -> 0 | I14: =+INDEX('2026-운영계획 PL'!$T:$AQ,ROW($B14),MATCH($J$1,'2026-운영계획 PL'!$T$1:$AQ$1,0)) -> 0 | J14: =IF($I$7=0,"",I14/$I$7) -> 0 | K14: =+INDEX('2026-실적 PL'!$O:$AL,ROW($B14),MATCH($J$1,'2026-실적 PL'!$O$1:$AL$1,0)) -> 0 | L14: =+IFERROR(K14/$K$7,0) -> 0 | M14: =IF(G14=0,"",K14/G14) | N14: =IF(I14=0,"",K14/I14) | P14: =K14-G14 -> 0 | Q14: =L14-H14 -> 0 | R14: =K14-I14 -> 0 | S14: =L14-J14 -> 0
B15: 03.수불무관매출 | C15: =+INDEX(#REF!,ROW('실적-PL 2026'!$B15),MATCH('실적-PL 2026'!$J$1,#REF!,0)) -> #REF! | D15: =IF($G$7=0,"",C15/$G$7) -> #REF! | E15: =+INDEX('2026-실적 PL'!$T:$AQ,ROW($B15),MATCH($J$2,'2026-실적 PL'!$T$1:$AQ$1,0)) -> 0 | F15: =+IFERROR(E15/$E$7,0) -> 0 | G15: =+INDEX('2026-사업계획-PL'!$T:$AQ,ROW($B15),MATCH($J$1,'2026-사업계획-PL'!$T$1:$AQ$1,0)) -> 0 | H15: =IF($G$7=0,"",G15/$G$7) -> 0 | I15: =+INDEX('2026-운영계획 PL'!$T:$AQ,ROW($B15),MATCH($J$1,'2026-운영계획 PL'!$T$1:$AQ$1,0)) -> 0 | J15: =IF($I$7=0,"",I15/$I$7) -> 0 | K15: =+INDEX('2026-실적 PL'!$O:$AL,ROW($B15),MATCH($J$1,'2026-실적 PL'!$O$1:$AL$1,0)) -> 0 | L15: =+IFERROR(K15/$K$7,0) -> 0 | M15: =IF(G15=0,"",K15/G15) | N15: =IF(I15=0,"",K15/I15) | P15: =K15-G15 -> 0 | Q15: =L15-H15 -> 0 | R15: =K15-I15 -> 0 | S15: =L15-J15 -> 0
B16: Ⅱ. 매출원가 | C16: =+INDEX(#REF!,ROW('실적-PL 2026'!$B16),MATCH('실적-PL 2026'!$J$1,#REF!,0)) -> #REF! | D16: =IF($G$7=0,"",C16/$G$7) -> #REF! | E16: =+INDEX('2026-실적 PL'!$T:$AQ,ROW($B16),MATCH($J$2,'2026-실적 PL'!$T$1:$AQ$1,0)) -> 0 | F16: =+IFERROR(E16/$E$7,0) -> 0 | G16: =+INDEX('2026-사업계획-PL'!$T:$AQ,ROW($B16),MATCH($J$1,'2026-사업계획-PL'!$T$1:$AQ$1,0)) -> 1.2607021e+11 | H16: =IF($G$7=0,"",G16/$G$7) -> 0.79541477 | I16: =+INDEX('2026-운영계획 PL'!$T:$AQ,ROW($B16),MATCH($J$1,'2026-운영계획 PL'!$T$1:$AQ$1,0)) -> 1.5881844e+11 | J16: =IF($I$7=0,"",I16/$I$7) -> 0.77346827 | K16: =+INDEX('2026-실적 PL'!$O:$AL,ROW($B16),MATCH($J$1,'2026-실적 PL'!$O$1:$AL$1,0)) -> 0 | L16: =+IFERROR(K16/$K$7,0) -> 0 | M16: =IF(G16=0,"",K16/G16) -> 0 | N16: =IF(I16=0,"",K16/I16) -> 0 | P16: =K16-G16 -> -1.2607021e+11 | Q16: =L16-H16 -> -0.79541477 | R16: =K16-I16 -> -1.5881844e+11 | S16: =L16-J16 -> -0.77346827
B17: 01. 제품매출원가 | C17: =+INDEX(#REF!,ROW('실적-PL 2026'!$B17),MATCH('실적-PL 2026'!$J$1,#REF!,0)) -> #REF! | D17: =IF($G$7=0,"",C17/$G$7) -> #REF! | E17: =+INDEX('2026-실적 PL'!$T:$AQ,ROW($B17),MATCH($J$2,'2026-실적 PL'!$T$1:$AQ$1,0)) -> 0 | F17: =+IFERROR(E17/$E$7,0) -> 0 | G17: =+INDEX('2026-사업계획-PL'!$T:$AQ,ROW($B17),MATCH($J$1,'2026-사업계획-PL'!$T$1:$AQ$1,0)) -> 1.2607021e+11 | H17: =IF($G$7=0,"",G17/$G$7) -> 0.79541477 | I17: =+INDEX('2026-운영계획 PL'!$T:$AQ,ROW($B17),MATCH($J$1,'2026-운영계획 PL'!$T$1:$AQ$1,0)) -> 1.5881844e+11 | J17: =IF($I$7=0,"",I17/$I$7) -> 0.77346827 | K17: =+INDEX('2026-실적 PL'!$O:$AL,ROW($B17),MATCH($J$1,'2026-실적 PL'!$O$1:$AL$1,0)) -> 0 | L17: =+IFERROR(K17/$K$7,0) -> 0 | M17: =IF(G17=0,"",K17/G17) -> 0 | N17: =IF(I17=0,"",K17/I17) -> 0 | P17: =K17-G17 -> -1.2607021e+11 | Q17: =L17-H17 -> -0.79541477 | R17: =K17-I17 -> -1.5881844e+11 | S17: =L17-J17 -> -0.77346827
B18: 기초제품재고액 | C18: =+INDEX(#REF!,ROW('실적-PL 2026'!$B18),MATCH('실적-PL 2026'!$J$1,#REF!,0)) -> #REF! | D18: =IF($G$7=0,"",C18/$G$7) -> #REF! | E18: =+INDEX('2026-실적 PL'!$T:$AQ,ROW($B18),MATCH($J$2,'2026-실적 PL'!$T$1:$AQ$1,0)) -> 0 | F18: =+IFERROR(E18/$E$7,0) -> 0 | G18: =+INDEX('2026-사업계획-PL'!$T:$AQ,ROW($B18),MATCH($J$1,'2026-사업계획-PL'!$T$1:$AQ$1,0)) -> 0 | H18: =IF($G$7=0,"",G18/$G$7) -> 0 | I18: =+INDEX('2026-운영계획 PL'!$T:$AQ,ROW($B18),MATCH($J$1,'2026-운영계획 PL'!$T$1:$AQ$1,0)) -> 0 | J18: =IF($I$7=0,"",I18/$I$7) -> 0 | K18: =+INDEX('2026-실적 PL'!$O:$AL,ROW($B18),MATCH($J$1,'2026-실적 PL'!$O$1:$AL$1,0)) -> 0 | L18: =+IFERROR(K18/$K$7,0) -> 0 | P18: =K18-G18 -> 0 | Q18: =L18-H18 -> 0 | R18: =K18-I18 -> 0 | S18: =L18-J18 -> 0
B19: 당기제품제조원가 | C19: =+INDEX(#REF!,ROW('실적-PL 2026'!$B19),MATCH('실적-PL 2026'!$J$1,#REF!,0)) -> #REF! | D19: =IF($G$7=0,"",C19/$G$7) -> #REF! | E19: =+INDEX('2026-실적 PL'!$T:$AQ,ROW($B19),MATCH($J$2,'2026-실적 PL'!$T$1:$AQ$1,0)) -> 0 | F19: =+IFERROR(E19/$E$7,0) -> 0 | G19: =+INDEX('2026-사업계획-PL'!$T:$AQ,ROW($B19),MATCH($J$1,'2026-사업계획-PL'!$T$1:$AQ$1,0)) -> 1.2607021e+11 | H19: =IF($G$7=0,"",G19/$G$7) -> 0.79541477 | I19: =+INDEX('2026-운영계획 PL'!$T:$AQ,ROW($B19),MATCH($J$1,'2026-운영계획 PL'!$T$1:$AQ$1,0)) -> 1.5881844e+11 | J19: =IF($I$7=0,"",I19/$I$7) -> 0.77346827 | K19: =+INDEX('2026-실적 PL'!$O:$AL,ROW($B19),MATCH($J$1,'2026-실적 PL'!$O$1:$AL$1,0)) -> 0 | L19: =+IFERROR(K19/$K$7,0) -> 0 | P19: =K19-G19 -> -1.2607021e+11 | Q19: =L19-H19 -> -0.79541477 | R19: =K19-I19 -> -1.5881844e+11 | S19: =L19-J19 -> -0.77346827
B20: 기말제품재고액 | C20: =+INDEX(#REF!,ROW('실적-PL 2026'!$B20),MATCH('실적-PL 2026'!$J$1,#REF!,0)) -> #REF! | D20: =IF($G$7=0,"",C20/$G$7) -> #REF! | E20: =+INDEX('2026-실적 PL'!$T:$AQ,ROW($B20),MATCH($J$2,'2026-실적 PL'!$T$1:$AQ$1,0)) -> 0 | F20: =+IFERROR(E20/$E$7,0) -> 0 | G20: =+INDEX('2026-사업계획-PL'!$T:$AQ,ROW($B20),MATCH($J$1,'2026-사업계획-PL'!$T$1:$AQ$1,0)) -> 0 | H20: =IF($G$7=0,"",G20/$G$7) -> 0 | I20: =+INDEX('2026-운영계획 PL'!$T:$AQ,ROW($B20),MATCH($J$1,'2026-운영계획 PL'!$T$1:$AQ$1,0)) -> 0 | J20: =IF($I$7=0,"",I20/$I$7) -> 0 | K20: =+INDEX('2026-실적 PL'!$O:$AL,ROW($B20),MATCH($J$1,'2026-실적 PL'!$O$1:$AL$1,0)) -> 0 | L20: =+IFERROR(K20/$K$7,0) -> 0 | P20: =K20-G20 -> 0 | Q20: =L20-H20 -> 0 | R20: =K20-I20 -> 0 | S20: =L20-J20 -> 0
B21: 02. 상품매출원가 | C21: =+INDEX(#REF!,ROW('실적-PL 2026'!$B21),MATCH('실적-PL 2026'!$J$1,#REF!,0)) -> #REF! | D21: =IF($G$7=0,"",C21/$G$7) -> #REF! | E21: =+INDEX('2026-실적 PL'!$T:$AQ,ROW($B21),MATCH($J$2,'2026-실적 PL'!$T$1:$AQ$1,0)) -> 0 | F21: =+IFERROR(E21/$E$7,0) -> 0 | G21: =+INDEX('2026-사업계획-PL'!$T:$AQ,ROW($B21),MATCH($J$1,'2026-사업계획-PL'!$T$1:$AQ$1,0)) -> 0 | H21: =IF($G$7=0,"",G21/$G$7) -> 0 | I21: =+INDEX('2026-운영계획 PL'!$T:$AQ,ROW($B21),MATCH($J$1,'2026-운영계획 PL'!$T$1:$AQ$1,0)) -> 0 | J21: =IF($I$7=0,"",I21/$I$7) -> 0 | K21: =+INDEX('2026-실적 PL'!$O:$AL,ROW($B21),MATCH($J$1,'2026-실적 PL'!$O$1:$AL$1,0)) -> 0 | L21: =+IFERROR(K21/$K$7,0) -> 0 | M21: =IF(G21=0,"",K21/G21) | N21: =IF(I21=0,"",K21/I21) | P21: =K21-G21 -> 0 | Q21: =L21-H21 -> 0 | R21: =K21-I21 -> 0 | S21: =L21-J21 -> 0
B22: (1) 국내매출원가-NET | C22: =+INDEX(#REF!,ROW('실적-PL 2026'!$B22),MATCH('실적-PL 2026'!$J$1,#REF!,0)) -> #REF! | D22: =IF($G$7=0,"",C22/$G$7) -> #REF! | E22: =+INDEX('2026-실적 PL'!$T:$AQ,ROW($B22),MATCH($J$2,'2026-실적 PL'!$T$1:$AQ$1,0)) -> 0 | F22: =+IFERROR(E22/$E$7,0) -> 0 | G22: =+INDEX('2026-사업계획-PL'!$T:$AQ,ROW($B22),MATCH($J$1,'2026-사업계획-PL'!$T$1:$AQ$1,0)) -> 0 | H22: =IF($G$7=0,"",G22/$G$7) -> 0 | I22: =+INDEX('2026-운영계획 PL'!$T:$AQ,ROW($B22),MATCH($J$1,'2026-운영계획 PL'!$T$1:$AQ$1,0)) -> 0 | J22: =IF($I$7=0,"",I22/$I$7) -> 0 | K22: =+INDEX('2026-실적 PL'!$O:$AL,ROW($B22),MATCH($J$1,'2026-실적 PL'!$O$1:$AL$1,0)) -> 0 | L22: =+IFERROR(K22/$K$7,0) -> 0 | P22: =K22-G22 -> 0 | Q22: =L22-H22 -> 0 | R22: =K22-I22 -> 0 | S22: =L22-J22 -> 0
B23: 국내매출원가-GROSS | C23: =+INDEX(#REF!,ROW('실적-PL 2026'!$B23),MATCH('실적-PL 2026'!$J$1,#REF!,0)) -> #REF! | D23: =IF($G$7=0,"",C23/$G$7) -> #REF! | E23: =+INDEX('2026-실적 PL'!$T:$AQ,ROW($B23),MATCH($J$2,'2026-실적 PL'!$T$1:$AQ$1,0)) -> 0 | F23: =+IFERROR(E23/$E$7,0) -> 0 | G23: =+INDEX('2026-사업계획-PL'!$T:$AQ,ROW($B23),MATCH($J$1,'2026-사업계획-PL'!$T$1:$AQ$1,0)) -> 0 | H23: =IF($G$7=0,"",G23/$G$7) -> 0 | I23: =+INDEX('2026-운영계획 PL'!$T:$AQ,ROW($B23),MATCH($J$1,'2026-운영계획 PL'!$T$1:$AQ$1,0)) -> 0 | J23: =IF($I$7=0,"",I23/$I$7) -> 0 | K23: =+INDEX('2026-실적 PL'!$O:$AL,ROW($B23),MATCH($J$1,'2026-실적 PL'!$O$1:$AL$1,0)) -> 0 | L23: =+IFERROR(K23/$K$7,0) -> 0 | M23: =IF(G23=0,"",K23/G23) | N23: =IF(I23=0,"",K23/I23) | P23: =K23-G23 -> 0 | Q23: =L23-H23 -> 0 | R23: =K23-I23 -> 0 | S23: =L23-J23 -> 0
B24: 기초상품재고액 | C24: =+INDEX(#REF!,ROW('실적-PL 2026'!$B24),MATCH('실적-PL 2026'!$J$1,#REF!,0)) -> #REF! | E24: =+INDEX('2026-실적 PL'!$T:$AQ,ROW($B24),MATCH($J$2,'2026-실적 PL'!$T$1:$AQ$1,0)) -> 0 | F24: =+IFERROR(E24/$E$7,0) -> 0 | G24: =+INDEX('2026-사업계획-PL'!$T:$AQ,ROW($B24),MATCH($J$1,'2026-사업계획-PL'!$T$1:$AQ$1,0)) -> 0 | I24: =+INDEX('2026-운영계획 PL'!$T:$AQ,ROW($B24),MATCH($J$1,'2026-운영계획 PL'!$T$1:$AQ$1,0)) -> 0 | K24: =+INDEX('2026-실적 PL'!$O:$AL,ROW($B24),MATCH($J$1,'2026-실적 PL'!$O$1:$AL$1,0)) -> 0 | L24: =+IFERROR(K24/$K$7,0) -> 0 | M24: =IF(G24=0,"",K24/G24) | P24: =K24-G24 -> 0 | Q24: =L24-H24 -> 0 | R24: =K24-I24 -> 0 | S24: =L24-J24 -> 0
B25: 당기상품매입액 | C25: =+INDEX(#REF!,ROW('실적-PL 2026'!$B25),MATCH('실적-PL 2026'!$J$1,#REF!,0)) -> #REF! | E25: =+INDEX('2026-실적 PL'!$T:$AQ,ROW($B25),MATCH($J$2,'2026-실적 PL'!$T$1:$AQ$1,0)) -> 0 | F25: =+IFERROR(E25/$E$7,0) -> 0 | G25: =+INDEX('2026-사업계획-PL'!$T:$AQ,ROW($B25),MATCH($J$1,'2026-사업계획-PL'!$T$1:$AQ$1,0)) -> 0 | I25: =+INDEX('2026-운영계획 PL'!$T:$AQ,ROW($B25),MATCH($J$1,'2026-운영계획 PL'!$T$1:$AQ$1,0)) -> 0 | K25: =+INDEX('2026-실적 PL'!$O:$AL,ROW($B25),MATCH($J$1,'2026-실적 PL'!$O$1:$AL$1,0)) -> 0 | L25: =+IFERROR(K25/$K$7,0) -> 0 | M25: =IF(G25=0,"",K25/G25) | P25: =K25-G25 -> 0 | Q25: =L25-H25 -> 0 | R25: =K25-I25 -> 0 | S25: =L25-J25 -> 0
B26: 기말상품재고액 | C26: =+INDEX(#REF!,ROW('실적-PL 2026'!$B26),MATCH('실적-PL 2026'!$J$1,#REF!,0)) -> #REF! | E26: =+INDEX('2026-실적 PL'!$T:$AQ,ROW($B26),MATCH($J$2,'2026-실적 PL'!$T$1:$AQ$1,0)) -> 0 | F26: =+IFERROR(E26/$E$7,0) -> 0 | G26: =+INDEX('2026-사업계획-PL'!$T:$AQ,ROW($B26),MATCH($J$1,'2026-사업계획-PL'!$T$1:$AQ$1,0)) -> 0 | I26: =+INDEX('2026-운영계획 PL'!$T:$AQ,ROW($B26),MATCH($J$1,'2026-운영계획 PL'!$T$1:$AQ$1,0)) -> 0 | K26: =+INDEX('2026-실적 PL'!$O:$AL,ROW($B26),MATCH($J$1,'2026-실적 PL'!$O$1:$AL$1,0)) -> 0 | L26: =+IFERROR(K26/$K$7,0) -> 0 | M26: =IF(G26=0,"",K26/G26) | P26: =K26-G26 -> 0 | Q26: =L26-H26 -> 0 | R26: =K26-I26 -> 0 | S26: =L26-J26 -> 0
B27: (2) 국외매출원가 - CKD | C27: =+INDEX(#REF!,ROW('실적-PL 2026'!$B27),MATCH('실적-PL 2026'!$J$1,#REF!,0)) -> #REF! | D27: =IF($G$7=0,"",C27/$G$7) -> #REF! | E27: =+INDEX('2026-실적 PL'!$T:$AQ,ROW($B27),MATCH($J$2,'2026-실적 PL'!$T$1:$AQ$1,0)) -> 0 | F27: =+IFERROR(E27/$E$7,0) -> 0 | G27: =+INDEX('2026-사업계획-PL'!$T:$AQ,ROW($B27),MATCH($J$1,'2026-사업계획-PL'!$T$1:$AQ$1,0)) -> 0 | H27: =IF($G$7=0,"",G27/$G$7) -> 0 | I27: =+INDEX('2026-운영계획 PL'!$T:$AQ,ROW($B27),MATCH($J$1,'2026-운영계획 PL'!$T$1:$AQ$1,0)) -> 0 | J27: =IF($I$7=0,"",I27/$I$7) -> 0 | K27: =+INDEX('2026-실적 PL'!$O:$AL,ROW($B27),MATCH($J$1,'2026-실적 PL'!$O$1:$AL$1,0)) -> 0 | L27: =+IFERROR(K27/$K$7,0) -> 0 | M27: =IF(G27=0,"",K27/G27) | N27: =IF(I27=0,"",K27/I27) | P27: =K27-G27 -> 0 | Q27: =L27-H27 -> 0 | R27: =K27-I27 -> 0 | S27: =L27-J27 -> 0
B28: Ⅲ. 매출총이익 | C28: =+INDEX(#REF!,ROW('실적-PL 2026'!$B28),MATCH('실적-PL 2026'!$J$1,#REF!,0)) -> #REF! | D28: =IF($G$7=0,"",C28/$G$7) -> #REF! | E28: =+INDEX('2026-실적 PL'!$T:$AQ,ROW($B28),MATCH($J$2,'2026-실적 PL'!$T$1:$AQ$1,0)) -> 0 | F28: =+IFERROR(E28/$E$7,0) -> 0 | G28: =+INDEX('2026-사업계획-PL'!$T:$AQ,ROW($B28),MATCH($J$1,'2026-사업계획-PL'!$T$1:$AQ$1,0)) -> 3.242598e+10 | H28: =IF($G$7=0,"",G28/$G$7) -> 0.20458523 | I28: =+INDEX('2026-운영계획 PL'!$T:$AQ,ROW($B28),MATCH($J$1,'2026-운영계획 PL'!$T$1:$AQ$1,0)) -> 4.6514404e+10 | J28: =IF($I$7=0,"",I28/$I$7) -> 0.22653173 | K28: =+INDEX('2026-실적 PL'!$O:$AL,ROW($B28),MATCH($J$1,'2026-실적 PL'!$O$1:$AL$1,0)) -> 0 | L28: =+IFERROR(K28/$K$7,0) -> 0 | M28: =IF(G28=0,"",K28/G28) -> 0 | N28: =IF(I28=0,"",K28/I28) -> 0 | P28: =K28-G28 -> -3.242598e+10 | Q28: =L28-H28 -> -0.20458523 | R28: =K28-I28 -> -4.6514404e+10 | S28: =L28-J28 -> -0.22653173
B29: Ⅳ. 판매비와 관리비 | C29: =+INDEX(#REF!,ROW('실적-PL 2026'!$B29),MATCH('실적-PL 2026'!$J$1,#REF!,0)) -> #REF! | D29: =IF($G$7=0,"",C29/$G$7) -> #REF! | E29: =+INDEX('2026-실적 PL'!$T:$AQ,ROW($B29),MATCH($J$2,'2026-실적 PL'!$T$1:$AQ$1,0)) -> 0 | F29: =+IFERROR(E29/$E$7,0) -> 0 | G29: =+INDEX('2026-사업계획-PL'!$T:$AQ,ROW($B29),MATCH($J$1,'2026-사업계획-PL'!$T$1:$AQ$1,0)) -> 1.927288e+10 | H29: =IF($G$7=0,"",G29/$G$7) -> 0.12159838 | I29: =+INDEX('2026-운영계획 PL'!$T:$AQ,ROW($B29),MATCH($J$1,'2026-운영계획 PL'!$T$1:$AQ$1,0)) -> 2.3147022e+10 | J29: =IF($I$7=0,"",I29/$I$7) -> 0.11272927 | K29: =+INDEX('2026-실적 PL'!$O:$AL,ROW($B29),MATCH($J$1,'2026-실적 PL'!$O$1:$AL$1,0)) -> 0 | L29: =+IFERROR(K29/$K$7,0) -> 0 | M29: =IF(G29=0,"",K29/G29) -> 0 | N29: =IF(I29=0,"",K29/I29) -> 0 | P29: =K29-G29 -> -1.927288e+10 | Q29: =L29-H29 -> -0.12159838 | R29: =K29-I29 -> -2.3147022e+10 | S29: =L29-J29 -> -0.11272927
B30: 01.급여 | C30: =+INDEX(#REF!,ROW('실적-PL 2026'!$B30),MATCH('실적-PL 2026'!$J$1,#REF!,0)) -> #REF! | D30: =IF($G$7=0,"",C30/$G$7) -> #REF! | E30: =+INDEX('2026-실적 PL'!$T:$AQ,ROW($B30),MATCH($J$2,'2026-실적 PL'!$T$1:$AQ$1,0)) -> 0 | F30: =+IFERROR(E30/$E$7,0) -> 0 | G30: =+INDEX('2026-사업계획-PL'!$T:$AQ,ROW($B30),MATCH($J$1,'2026-사업계획-PL'!$T$1:$AQ$1,0)) -> 815816000 | H30: =IF($G$7=0,"",G30/$G$7) -> 0.0051472277 | I30: =+INDEX('2026-운영계획 PL'!$T:$AQ,ROW($B30),MATCH($J$1,'2026-운영계획 PL'!$T$1:$AQ$1,0)) -> 881081280 | J30: =IF($I$7=0,"",I30/$I$7) -> 0.0042909905 | K30: =+INDEX('2026-실적 PL'!$O:$AL,ROW($B30),MATCH($J$1,'2026-실적 PL'!$O$1:$AL$1,0)) -> 0 | L30: =+IFERROR(K30/$K$7,0) -> 0 | M30: =IF(G30=0,"",K30/G30) -> 0 | N30: =IF(I30=0,"",K30/I30) -> 0 | P30: =K30-G30 -> -815816000 | Q30: =L30-H30 -> -0.0051472277 | R30: =K30-I30 -> -881081280 | S30: =L30-J30 -> -0.0042909905
B31: '01.1 급여-4대보험 | E31: =+INDEX('2026-실적 PL'!$T:$AQ,ROW($B31),MATCH($J$2,'2026-실적 PL'!$T$1:$AQ$1,0)) -> 0 | F31: =+IFERROR(E31/$E$7,0) -> 0 | G31: =+INDEX('2026-사업계획-PL'!$T:$AQ,ROW($B31),MATCH($J$1,'2026-사업계획-PL'!$T$1:$AQ$1,0)) -> 79106380 | H31: =IF($G$7=0,"",G31/$G$7) -> 0.00049910586 | I31: =+INDEX('2026-운영계획 PL'!$T:$AQ,ROW($B31),MATCH($J$1,'2026-운영계획 PL'!$T$1:$AQ$1,0)) -> 79106380 | J31: =IF($I$7=0,"",I31/$I$7) -> 0.00038525927 | K31: =+INDEX('2026-실적 PL'!$O:$AL,ROW($B31),MATCH($J$1,'2026-실적 PL'!$O$1:$AL$1,0)) -> 0 | L31: =+IFERROR(K31/$K$7,0) -> 0 | M31: =IF(G31=0,"",K31/G31) -> 0 | N31: =IF(I31=0,"",K31/I31) -> 0
B32: 02.잡급 | C32: =+INDEX(#REF!,ROW('실적-PL 2026'!$B32),MATCH('실적-PL 2026'!$J$1,#REF!,0)) -> #REF! | D32: =IF($G$7=0,"",C32/$G$7) -> #REF! | E32: =+INDEX('2026-실적 PL'!$T:$AQ,ROW($B32),MATCH($J$2,'2026-실적 PL'!$T$1:$AQ$1,0)) -> 0 | F32: =+IFERROR(E32/$E$7,0) -> 0 | G32: =+INDEX('2026-사업계획-PL'!$T:$AQ,ROW($B32),MATCH($J$1,'2026-사업계획-PL'!$T$1:$AQ$1,0)) -> 257240000 | H32: =IF($G$7=0,"",G32/$G$7) -> 0.0016230043 | I32: =+INDEX('2026-운영계획 PL'!$T:$AQ,ROW($B32),MATCH($J$1,'2026-운영계획 PL'!$T$1:$AQ$1,0)) -> 257240000 | J32: =IF($I$7=0,"",I32/$I$7) -> 0.0012527952 | K32: =+INDEX('2026-실적 PL'!$O:$AL,ROW($B32),MATCH($J$1,'2026-실적 PL'!$O$1:$AL$1,0)) -> 0 | L32: =+IFERROR(K32/$K$7,0) -> 0 | M32: =IF(G32=0,"",K32/G32) -> 0 | N32: =IF(I32=0,"",K32/I32) -> 0 | P32: =K32-G32 -> -257240000 | Q32: =L32-H32 -> -0.0016230043 | R32: =K32-I32 -> -257240000 | S32: =L32-J32 -> -0.0012527952
B33: 03.퇴직급여 | C33: =+INDEX(#REF!,ROW('실적-PL 2026'!$B33),MATCH('실적-PL 2026'!$J$1,#REF!,0)) -> #REF! | D33: =IF($G$7=0,"",C33/$G$7) -> #REF! | E33: =+INDEX('2026-실적 PL'!$T:$AQ,ROW($B33),MATCH($J$2,'2026-실적 PL'!$T$1:$AQ$1,0)) -> 0 | F33: =+IFERROR(E33/$E$7,0) -> 0 | G33: =+INDEX('2026-사업계획-PL'!$T:$AQ,ROW($B33),MATCH($J$1,'2026-사업계획-PL'!$T$1:$AQ$1,0)) -> 0 | H33: =IF($G$7=0,"",G33/$G$7) -> 0 | I33: =+INDEX('2026-운영계획 PL'!$T:$AQ,ROW($B33),MATCH($J$1,'2026-운영계획 PL'!$T$1:$AQ$1,0)) -> 0 | J33: =IF($I$7=0,"",I33/$I$7) -> 0 | K33: =+INDEX('2026-실적 PL'!$O:$AL,ROW($B33),MATCH($J$1,'2026-실적 PL'!$O$1:$AL$1,0)) -> 0 | L33: =+IFERROR(K33/$K$7,0) -> 0 | M33: =IF(G33=0,"",K33/G33) | N33: =IF(I33=0,"",K33/I33) | P33: =K33-G33 -> 0 | Q33: =L33-H33 -> 0 | R33: =K33-I33 -> 0 | S33: =L33-J33 -> 0
B34: 04.복리후생비 | C34: =+INDEX(#REF!,ROW('실적-PL 2026'!$B34),MATCH('실적-PL 2026'!$J$1,#REF!,0)) -> #REF! | D34: =IF($G$7=0,"",C34/$G$7) -> #REF! | E34: =+INDEX('2026-실적 PL'!$T:$AQ,ROW($B34),MATCH($J$2,'2026-실적 PL'!$T$1:$AQ$1,0)) -> 0 | F34: =+IFERROR(E34/$E$7,0) -> 0 | G34: =+INDEX('2026-사업계획-PL'!$T:$AQ,ROW($B34),MATCH($J$1,'2026-사업계획-PL'!$T$1:$AQ$1,0)) -> 87696000 | H34: =IF($G$7=0,"",G34/$G$7) -> 0.00055330035 | I34: =+INDEX('2026-운영계획 PL'!$T:$AQ,ROW($B34),MATCH($J$1,'2026-운영계획 PL'!$T$1:$AQ$1,0)) -> 87696000 | J34: =IF($I$7=0,"",I34/$I$7) -> 0.00042709193 | K34: =+INDEX('2026-실적 PL'!$O:$AL,ROW($B34),MATCH($J$1,'2026-실적 PL'!$O$1:$AL$1,0)) -> 0 | L34: =+IFERROR(K34/$K$7,0) -> 0 | M34: =IF(G34=0,"",K34/G34) -> 0 | N34: =IF(I34=0,"",K34/I34) -> 0 | P34: =K34-G34 -> -87696000 | Q34: =L34-H34 -> -0.00055330035 | R34: =K34-I34 -> -87696000 | S34: =L34-J34 -> -0.00042709193
B35: 05.여비교통비 | C35: =+INDEX(#REF!,ROW('실적-PL 2026'!$B35),MATCH('실적-PL 2026'!$J$1,#REF!,0)) -> #REF! | D35: =IF($G$7=0,"",C35/$G$7) -> #REF! | E35: =+INDEX('2026-실적 PL'!$T:$AQ,ROW($B35),MATCH($J$2,'2026-실적 PL'!$T$1:$AQ$1,0)) -> 0 | F35: =+IFERROR(E35/$E$7,0) -> 0 | G35: =+INDEX('2026-사업계획-PL'!$T:$AQ,ROW($B35),MATCH($J$1,'2026-사업계획-PL'!$T$1:$AQ$1,0)) -> 7000000 | H35: =IF($G$7=0,"",G35/$G$7) -> 4.4165098e-05 | I35: =+INDEX('2026-운영계획 PL'!$T:$AQ,ROW($B35),MATCH($J$1,'2026-운영계획 PL'!$T$1:$AQ$1,0)) -> 7000000 | J35: =IF($I$7=0,"",I35/$I$7) -> 3.4090991e-05 | K35: =+INDEX('2026-실적 PL'!$O:$AL,ROW($B35),MATCH($J$1,'2026-실적 PL'!$O$1:$AL$1,0)) -> 0 | L35: =+IFERROR(K35/$K$7,0) -> 0 | M35: =IF(G35=0,"",K35/G35) -> 0 | N35: =IF(I35=0,"",K35/I35) -> 0 | P35: =K35-G35 -> -7000000 | Q35: =L35-H35 -> -4.4165098e-05 | R35: =K35-I35 -> -7000000 | S35: =L35-J35 -> -3.4090991e-05
B36: 06.접대비 | C36: =+INDEX(#REF!,ROW('실적-PL 2026'!$B36),MATCH('실적-PL 2026'!$J$1,#REF!,0)) -> #REF! | D36: =IF($G$7=0,"",C36/$G$7) -> #REF! | E36: =+INDEX('2026-실적 PL'!$T:$AQ,ROW($B36),MATCH($J$2,'2026-실적 PL'!$T$1:$AQ$1,0)) -> 0 | F36: =+IFERROR(E36/$E$7,0) -> 0 | G36: =+INDEX('2026-사업계획-PL'!$T:$AQ,ROW($B36),MATCH($J$1,'2026-사업계획-PL'!$T$1:$AQ$1,0)) -> 20000000 | H36: =IF($G$7=0,"",G36/$G$7) -> 0.00012618599 | I36: =+INDEX('2026-운영계획 PL'!$T:$AQ,ROW($B36),MATCH($J$1,'2026-운영계획 PL'!$T$1:$AQ$1,0)) -> 20000000 | J36: =IF($I$7=0,"",I36/$I$7) -> 9.7402831e-05 | K36: =+INDEX('2026-실적 PL'!$O:$AL,ROW($B36),MATCH($J$1,'2026-실적 PL'!$O$1:$AL$1,0)) -> 0 | L36: =+IFERROR(K36/$K$7,0) -> 0 | M36: =IF(G36=0,"",K36/G36) -> 0 | N36: =IF(I36=0,"",K36/I36) -> 0 | P36: =K36-G36 -> -20000000 | Q36: =L36-H36 -> -0.00012618599 | R36: =K36-I36 -> -20000000 | S36: =L36-J36 -> -9.7402831e-05
B37: 07.통신비 | C37: =+INDEX(#REF!,ROW('실적-PL 2026'!$B37),MATCH('실적-PL 2026'!$J$1,#REF!,0)) -> #REF! | D37: =IF($G$7=0,"",C37/$G$7) -> #REF! | E37: =+INDEX('2026-실적 PL'!$T:$AQ,ROW($B37),MATCH($J$2,'2026-실적 PL'!$T$1:$AQ$1,0)) -> 0 | F37: =+IFERROR(E37/$E$7,0) -> 0 | G37: =+INDEX('2026-사업계획-PL'!$T:$AQ,ROW($B37),MATCH($J$1,'2026-사업계획-PL'!$T$1:$AQ$1,0)) -> 8400000 | H37: =IF($G$7=0,"",G37/$G$7) -> 5.2998118e-05 | I37: =+INDEX('2026-운영계획 PL'!$T:$AQ,ROW($B37),MATCH($J$1,'2026-운영계획 PL'!$T$1:$AQ$1,0)) -> 8400000 | J37: =IF($I$7=0,"",I37/$I$7) -> 4.0909189e-05 | K37: =+INDEX('2026-실적 PL'!$O:$AL,ROW($B37),MATCH($J$1,'2026-실적 PL'!$O$1:$AL$1,0)) -> 0 | L37: =+IFERROR(K37/$K$7,0) -> 0 | M37: =IF(G37=0,"",K37/G37) -> 0 | N37: =IF(I37=0,"",K37/I37) -> 0 | P37: =K37-G37 -> -8400000 | Q37: =L37-H37 -> -5.2998118e-05 | R37: =K37-I37 -> -8400000 | S37: =L37-J37 -> -4.0909189e-05
B38: 08.수도광열비 | C38: =+INDEX(#REF!,ROW('실적-PL 2026'!$B38),MATCH('실적-PL 2026'!$J$1,#REF!,0)) -> #REF! | D38: =IF($G$7=0,"",C38/$G$7) -> #REF! | E38: =+INDEX('2026-실적 PL'!$T:$AQ,ROW($B38),MATCH($J$2,'2026-실적 PL'!$T$1:$AQ$1,0)) -> 0 | F38: =+IFERROR(E38/$E$7,0) -> 0 | G38: =+INDEX('2026-사업계획-PL'!$T:$AQ,ROW($B38),MATCH($J$1,'2026-사업계획-PL'!$T$1:$AQ$1,0)) -> 106700000 | H38: =IF($G$7=0,"",G38/$G$7) -> 0.00067320228 | I38: =+INDEX('2026-운영계획 PL'!$T:$AQ,ROW($B38),MATCH($J$1,'2026-운영계획 PL'!$T$1:$AQ$1,0)) -> 106700000 | J38: =IF($I$7=0,"",I38/$I$7) -> 0.0005196441 | K38: =+INDEX('2026-실적 PL'!$O:$AL,ROW($B38),MATCH($J$1,'2026-실적 PL'!$O$1:$AL$1,0)) -> 0 | L38: =+IFERROR(K38/$K$7,0) -> 0 | M38: =IF(G38=0,"",K38/G38) -> 0 | N38: =IF(I38=0,"",K38/I38) -> 0 | P38: =K38-G38 -> -106700000 | Q38: =L38-H38 -> -0.00067320228 | R38: =K38-I38 -> -106700000 | S38: =L38-J38 -> -0.0005196441
B39: 09.세금과공과 | C39: =+INDEX(#REF!,ROW('실적-PL 2026'!$B39),MATCH('실적-PL 2026'!$J$1,#REF!,0)) -> #REF! | D39: =IF($G$7=0,"",C39/$G$7) -> #REF! | E39: =+INDEX('2026-실적 PL'!$T:$AQ,ROW($B39),MATCH($J$2,'2026-실적 PL'!$T$1:$AQ$1,0)) -> 0 | F39: =+IFERROR(E39/$E$7,0) -> 0 | G39: =+INDEX('2026-사업계획-PL'!$T:$AQ,ROW($B39),MATCH($J$1,'2026-사업계획-PL'!$T$1:$AQ$1,0)) -> 25000000 | H39: =IF($G$7=0,"",G39/$G$7) -> 0.00015773249 | I39: =+INDEX('2026-운영계획 PL'!$T:$AQ,ROW($B39),MATCH($J$1,'2026-운영계획 PL'!$T$1:$AQ$1,0)) -> 25000000 | J39: =IF($I$7=0,"",I39/$I$7) -> 0.00012175354 | K39: =+INDEX('2026-실적 PL'!$O:$AL,ROW($B39),MATCH($J$1,'2026-실적 PL'!$O$1:$AL$1,0)) -> 0 | L39: =+IFERROR(K39/$K$7,0) -> 0 | M39: =IF(G39=0,"",K39/G39) -> 0 | N39: =IF(I39=0,"",K39/I39) -> 0 | P39: =K39-G39 -> -25000000 | Q39: =L39-H39 -> -0.00015773249 | R39: =K39-I39 -> -25000000 | S39: =L39-J39 -> -0.00012175354
B40: 10.감가상각비 | C40: =+INDEX(#REF!,ROW('실적-PL 2026'!$B40),MATCH('실적-PL 2026'!$J$1,#REF!,0)) -> #REF! | D40: =IF($G$7=0,"",C40/$G$7) -> #REF! | E40: =+INDEX('2026-실적 PL'!$T:$AQ,ROW($B40),MATCH($J$2,'2026-실적 PL'!$T$1:$AQ$1,0)) -> 0 | F40: =+IFERROR(E40/$E$7,0) -> 0 | G40: =+INDEX('2026-사업계획-PL'!$T:$AQ,ROW($B40),MATCH($J$1,'2026-사업계획-PL'!$T$1:$AQ$1,0)) -> 4.0524877e+08 | H40: =IF($G$7=0,"",G40/$G$7) -> 0.0025568359 | I40: =+INDEX('2026-운영계획 PL'!$T:$AQ,ROW($B40),MATCH($J$1,'2026-운영계획 PL'!$T$1:$AQ$1,0)) -> 4.0524877e+08 | J40: =IF($I$7=0,"",I40/$I$7) -> 0.0019736189 | K40: =+INDEX('2026-실적 PL'!$O:$AL,ROW($B40),MATCH($J$1,'2026-실적 PL'!$O$1:$AL$1,0)) -> 0 | L40: =+IFERROR(K40/$K$7,0) -> 0 | M40: =IF(G40=0,"",K40/G40) -> 0 | N40: =IF(I40=0,"",K40/I40) -> 0 | P40: =K40-G40 -> -4.0524877e+08 | Q40: =L40-H40 -> -0.0025568359 | R40: =K40-I40 -> -4.0524877e+08 | S40: =L40-J40 -> -0.0019736189
...

Sheet 실적-MC 2026
B1: =+'실적-PL 2026'!B1 -> 7월 목표vs실적- 베트남 | I1: 월 | J1: =+'실적-PL 2026'!J1 -> 7
I2: 전월 | J2: =+IF(J1-1=0,12,J1-1) -> 6
B3: 제조원가명세서 (현지통화} | K3: =+K10+K11-#REF! -> #REF! | M3: (단위: VND )
B4: 계정과목 | C4: 전년동월 | E4: 전월 | G4: 사업목표 | I4: 운영목표 | K4: 실적 | M4: 달성율 | P4: 차이
P5: 사업목표 VS 실적 | R5: 운영목표 VS 실적 | T5: 요약 내용
C6: 금액 | D6: 비율 | E6: 금액 | F6: 비율 | G6: 금액 | H6: 비율 | I6: 금액 | J6: 비율 | K6: 금액 | L6: 비율 | M6: 사업목표 대비 | N6: 운영목표 대비 | P6: 금액 | Q6: 비율 | R6: 금액 | S6: 비율
B7: ★ 생 산 액 | C7: =+INDEX(#REF!,ROW('실적-MC 2026'!$B7),MATCH('실적-MC 2026'!$J$1,#REF!,0)) -> #REF! | D7: =+IFERROR(C7/$C$7,0) -> 0 | E7: =+INDEX('2026-실적-MC'!$T:$AQ,ROW('실적-MC 2026'!$B7),MATCH($J$2,'2026-실적-MC'!$T$1:$AQ$1,0)) -> 0 | F7: =+IFERROR(E7/$E$7,0) -> 0 | G7: =+INDEX('2026-사업계획-MC'!$T:$AQ,ROW('실적-MC 2026'!$B7),MATCH($J$1,'2026-사업계획-MC'!$T$1:$AQ$1,0)) -> 1.5849619e+11 | H7: =+IFERROR(G7/$G$7,0) -> 1 | I7: =+INDEX('2026-운영계획-MC'!$T:$AQ,ROW('실적-MC 2026'!$B7),MATCH($J$1,'2026-운영계획-MC'!$T$1:$AQ$1,0)) -> 1.9344133e+11 | J7: =+IFERROR(I7/$I$7,0) -> 1 | K7: =+INDEX('2026-실적-MC'!$O:$AL,ROW('실적-MC 2026'!$B7),MATCH($J$1,'2026-실적-MC'!$O$1:$AL$1,0)) -> 0 | L7: =+IFERROR(K7/$K$7,0) -> 0 | M7: =IF(G7=0,"",K7/G7) -> 0 | N7: =IF(I7=0,"",K7/I7) -> 0 | P7: =K7-G7 -> -1.5849619e+11 | Q7: =L7-H7 -> -1 | R7: =K7-I7 -> -1.9344133e+11 | S7: =L7-J7 -> -1
B8: Ⅰ.원재료비 | C8: =+INDEX(#REF!,ROW('실적-MC 2026'!$B8),MATCH('실적-MC 2026'!$J$1,#REF!,0)) -> #REF! | D8: =+IFERROR(C8/$C$7,0) -> 0 | E8: =+INDEX('2026-실적-MC'!$T:$AQ,ROW('실적-MC 2026'!$B8),MATCH($J$2,'2026-실적-MC'!$T$1:$AQ$1,0)) -> 0 | F8: =+IFERROR(E8/$E$7,0) -> 0 | G8: =+INDEX('2026-사업계획-MC'!$T:$AQ,ROW('실적-MC 2026'!$B8),MATCH($J$1,'2026-사업계획-MC'!$T$1:$AQ$1,0)) -> 1.0978891e+11 | H8: =+IFERROR(G8/$G$7,0) -> 0.69269114 | I8: =+INDEX('2026-운영계획-MC'!$T:$AQ,ROW('실적-MC 2026'!$B8),MATCH($J$1,'2026-운영계획-MC'!$T$1:$AQ$1,0)) -> 1.3927899e+11 | J8: =+IFERROR(I8/$I$7,0) -> 0.72000637 | K8: =+INDEX('2026-실적-MC'!$O:$AL,ROW('실적-MC 2026'!$B8),MATCH($J$1,'2026-실적-MC'!$O$1:$AL$1,0)) -> 0 | L8: =+IFERROR(K8/$K$7,0) -> 0 | M8: =IF(G8=0,"",K8/G8) -> 0 | N8: =IF(I8=0,"",K8/I8) -> 0 | P8: =K8-G8 -> -1.0978891e+11 | Q8: =L8-H8 -> -0.69269114 | R8: =K8-I8 -> -1.3927899e+11 | S8: =L8-J8 -> -0.72000637
B9: 01.기초원재료재고액 | C9: =+INDEX(#REF!,ROW('실적-MC 2026'!$B9),MATCH('실적-MC 2026'!$J$1,#REF!,0)) -> #REF! | D9: =+IFERROR(C9/$C$7,0) -> 0 | E9: =+INDEX('2026-실적-MC'!$T:$AQ,ROW('실적-MC 2026'!$B9),MATCH($J$2,'2026-실적-MC'!$T$1:$AQ$1,0)) -> 0 | G9: =+INDEX('2026-사업계획-MC'!$T:$AQ,ROW('실적-MC 2026'!$B9),MATCH($J$1,'2026-사업계획-MC'!$T$1:$AQ$1,0)) -> 0 | H9: =+IFERROR(G9/$G$7,0) -> 0 | I9: =+INDEX('2026-운영계획-MC'!$T:$AQ,ROW('실적-MC 2026'!$B9),MATCH($J$1,'2026-운영계획-MC'!$T$1:$AQ$1,0)) -> 0 | J9: =+IFERROR(I9/$I$7,0) -> 0 | K9: =+INDEX('2026-실적-MC'!$O:$AL,ROW('실적-MC 2026'!$B9),MATCH($J$1,'2026-실적-MC'!$O$1:$AL$1,0)) -> 0 | M9: =IF(G9=0,"",K9/G9) | N9: =IF(I9=0,"",K9/I9) | P9: =K9-G9 -> 0 | Q9: =L9-H9 -> 0 | R9: =K9-I9 -> 0 | S9: =L9-J9 -> 0
B10: 02.당기원재료매입액(CKD) | C10: =+INDEX(#REF!,ROW('실적-MC 2026'!$B10),MATCH('실적-MC 2026'!$J$1,#REF!,0)) -> #REF! | D10: =+IFERROR(C10/$C$7,0) -> 0 | E10: =+INDEX('2026-실적-MC'!$T:$AQ,ROW('실적-MC 2026'!$B10),MATCH($J$2,'2026-실적-MC'!$T$1:$AQ$1,0)) -> 0 | F10: =+IFERROR(E10/$E$7,0) -> 0 | G10: =+INDEX('2026-사업계획-MC'!$T:$AQ,ROW('실적-MC 2026'!$B10),MATCH($J$1,'2026-사업계획-MC'!$T$1:$AQ$1,0)) -> 7.393811e+10 | H10: =+IFERROR(G10/$G$7,0) -> 0.4664977 | I10: =+INDEX('2026-운영계획-MC'!$T:$AQ,ROW('실적-MC 2026'!$B10),MATCH($J$1,'2026-운영계획-MC'!$T$1:$AQ$1,0)) -> 9.3957636e+10 | J10: =+IFERROR(I10/$I$7,0) -> 0.48571645 | K10: =+INDEX('2026-실적-MC'!$O:$AL,ROW('실적-MC 2026'!$B10),MATCH($J$1,'2026-실적-MC'!$O$1:$AL$1,0)) -> 0 | L10: =+IFERROR(K10/$K$7,0) -> 0 | M10: =IF(G10=0,"",K10/G10) -> 0 | N10: =IF(I10=0,"",K10/I10) -> 0 | P10: =K10-G10 -> -7.393811e+10 | Q10: =L10-H10 -> -0.4664977 | R10: =K10-I10 -> -9.3957636e+10 | S10: =L10-J10 -> -0.48571645
B11: 03.당기원재료매입액(LP) | C11: =+INDEX(#REF!,ROW('실적-MC 2026'!$B11),MATCH('실적-MC 2026'!$J$1,#REF!,0)) -> #REF! | D11: =+IFERROR(C11/$C$7,0) -> 0 | E11: =+INDEX('2026-실적-MC'!$T:$AQ,ROW('실적-MC 2026'!$B11),MATCH($J$2,'2026-실적-MC'!$T$1:$AQ$1,0)) -> 0 | F11: =+IFERROR(E11/$E$7,0) -> 0 | G11: =+INDEX('2026-사업계획-MC'!$T:$AQ,ROW('실적-MC 2026'!$B11),MATCH($J$1,'2026-사업계획-MC'!$T$1:$AQ$1,0)) -> 3.5850799e+10 | H11: =+IFERROR(G11/$G$7,0) -> 0.22619343 | I11: =+INDEX('2026-운영계획-MC'!$T:$AQ,ROW('실적-MC 2026'!$B11),MATCH($J$1,'2026-운영계획-MC'!$T$1:$AQ$1,0)) -> 4.5321353e+10 | J11: =+IFERROR(I11/$I$7,0) -> 0.23428992 | K11: =+INDEX('2026-실적-MC'!$O:$AL,ROW('실적-MC 2026'!$B11),MATCH($J$1,'2026-실적-MC'!$O$1:$AL$1,0)) -> 0 | L11: =+IFERROR(K11/$K$7,0) -> 0 | M11: =IF(G11=0,"",K11/G11) -> 0 | N11: =IF(I11=0,"",K11/I11) -> 0 | P11: =K11-G11 -> -3.5850799e+10 | Q11: =L11-H11 -> -0.22619343 | R11: =K11-I11 -> -4.5321353e+10 | S11: =L11-J11 -> -0.23428992
B12: 04.기말원재료재고액 | C12: =+INDEX(#REF!,ROW('실적-MC 2026'!$B12),MATCH('실적-MC 2026'!$J$1,#REF!,0)) -> #REF! | D12: =+IFERROR(C12/$C$7,0) -> 0 | E12: =+INDEX('2026-실적-MC'!$T:$AQ,ROW('실적-MC 2026'!$B12),MATCH($J$2,'2026-실적-MC'!$T$1:$AQ$1,0)) -> 0 | G12: =+INDEX('2026-사업계획-MC'!$T:$AQ,ROW('실적-MC 2026'!$B12),MATCH($J$1,'2026-사업계획-MC'!$T$1:$AQ$1,0)) -> 0 | H12: =+IFERROR(G12/$G$7,0) -> 0 | I12: =+INDEX('2026-운영계획-MC'!$T:$AQ,ROW('실적-MC 2026'!$B12),MATCH($J$1,'2026-운영계획-MC'!$T$1:$AQ$1,0)) -> 0 | J12: =+IFERROR(I12/$I$7,0) -> 0 | K12: =+INDEX('2026-실적-MC'!$O:$AL,ROW('실적-MC 2026'!$B12),MATCH($J$1,'2026-실적-MC'!$O$1:$AL$1,0)) -> 0 | M12: =IF(G12=0,"",K12/G12) | N12: =IF(I12=0,"",K12/I12) | P12: =K12-G12 -> 0 | Q12: =L12-H12 -> 0 | R12: =K12-I12 -> 0 | S12: =L12-J12 -> 0
B13: Ⅱ. 노무비 | C13: =+INDEX(#REF!,ROW('실적-MC 2026'!$B13),MATCH('실적-MC 2026'!$J$1,#REF!,0)) -> #REF! | D13: =+IFERROR(C13/$C$7,0) -> 0 | E13: =+INDEX('2026-실적-MC'!$T:$AQ,ROW('실적-MC 2026'!$B13),MATCH($J$2,'2026-실적-MC'!$T$1:$AQ$1,0)) -> 0 | F13: =+IFERROR(E13/$E$7,0) -> 0 | G13: =+INDEX('2026-사업계획-MC'!$T:$AQ,ROW('실적-MC 2026'!$B13),MATCH($J$1,'2026-사업계획-MC'!$T$1:$AQ$1,0)) -> 6.8731684e+09 | H13: =+IFERROR(G13/$G$7,0) -> 0.04336488 | I13: =+INDEX('2026-운영계획-MC'!$T:$AQ,ROW('실적-MC 2026'!$B13),MATCH($J$1,'2026-운영계획-MC'!$T$1:$AQ$1,0)) -> 9.2574611e+09 | J13: =+IFERROR(I13/$I$7,0) -> 0.047856687 | K13: =+INDEX('2026-실적-MC'!$O:$AL,ROW('실적-MC 2026'!$B13),MATCH($J$1,'2026-실적-MC'!$O$1:$AL$1,0)) -> 0 | L13: =+IFERROR(K13/$K$7,0) -> 0 | M13: =IF(G13=0,"",K13/G13) -> 0 | N13: =IF(I13=0,"",K13/I13) -> 0 | P13: =K13-G13 -> -6.8731684e+09 | Q13: =L13-H13 -> -0.04336488 | R13: =K13-I13 -> -9.2574611e+09 | S13: =L13-J13 -> -0.047856687
B14: 01.급여 | C14: =+INDEX(#REF!,ROW('실적-MC 2026'!$B14),MATCH('실적-MC 2026'!$J$1,#REF!,0)) -> #REF! | D14: =+IFERROR(C14/$C$7,0) -> 0 | E14: =+INDEX('2026-실적-MC'!$T:$AQ,ROW('실적-MC 2026'!$B14),MATCH($J$2,'2026-실적-MC'!$T$1:$AQ$1,0)) -> 0 | F14: =+IFERROR(E14/$E$7,0) -> 0 | G14: =+INDEX('2026-사업계획-MC'!$T:$AQ,ROW('실적-MC 2026'!$B14),MATCH($J$1,'2026-사업계획-MC'!$T$1:$AQ$1,0)) -> 5.9916981e+09 | H14: =+IFERROR(G14/$G$7,0) -> 0.037803419 | I14: =+INDEX('2026-운영계획-MC'!$T:$AQ,ROW('실적-MC 2026'!$B14),MATCH($J$1,'2026-운영계획-MC'!$T$1:$AQ$1,0)) -> 8.5082113e+09 | J14: =+IFERROR(I14/$I$7,0) -> 0.043983421 | K14: =+INDEX('2026-실적-MC'!$O:$AL,ROW('실적-MC 2026'!$B14),MATCH($J$1,'2026-실적-MC'!$O$1:$AL$1,0)) -> 0 | L14: =+IFERROR(K14/$K$7,0) -> 0 | M14: =IF(G14=0,"",K14/G14) -> 0 | N14: =IF(I14=0,"",K14/I14) -> 0 | P14: =K14-G14 -> -5.9916981e+09 | Q14: =L14-H14 -> -0.037803419 | R14: =K14-I14 -> -8.5082113e+09 | S14: =L14-J14 -> -0.043983421
B15: 02.급여-4대보험 | C15: =+INDEX(#REF!,ROW('실적-MC 2026'!$B15),MATCH('실적-MC 2026'!$J$1,#REF!,0)) -> #REF! | D15: =+IFERROR(C15/$C$7,0) -> 0 | E15: =+INDEX('2026-실적-MC'!$T:$AQ,ROW('실적-MC 2026'!$B15),MATCH($J$2,'2026-실적-MC'!$T$1:$AQ$1,0)) -> 0 | F15: =+IFERROR(E15/$E$7,0) -> 0 | G15: =+INDEX('2026-사업계획-MC'!$T:$AQ,ROW('실적-MC 2026'!$B15),MATCH($J$1,'2026-사업계획-MC'!$T$1:$AQ$1,0)) -> 881470280 | H15: =+IFERROR(G15/$G$7,0) -> 0.0055614602 | I15: =+INDEX('2026-운영계획-MC'!$T:$AQ,ROW('실적-MC 2026'!$B15),MATCH($J$1,'2026-운영계획-MC'!$T$1:$AQ$1,0)) -> 749249738 | J15: =+IFERROR(I15/$I$7,0) -> 0.0038732661 | K15: =+INDEX('2026-실적-MC'!$O:$AL,ROW('실적-MC 2026'!$B15),MATCH($J$1,'2026-실적-MC'!$O$1:$AL$1,0)) -> 0 | L15: =+IFERROR(K15/$K$7,0) -> 0 | M15: =IF(G15=0,"",K15/G15) -> 0 | N15: =IF(I15=0,"",K15/I15) -> 0 | P15: =K15-G15 -> -881470280 | Q15: =L15-H15 -> -0.0055614602 | R15: =K15-I15 -> -749249738 | S15: =L15-J15 -> -0.0038732661
B16: 03.퇴직급여 | C16: =+INDEX(#REF!,ROW('실적-MC 2026'!$B16),MATCH('실적-MC 2026'!$J$1,#REF!,0)) -> #REF! | D16: =+IFERROR(C16/$C$7,0) -> 0 | E16: =+INDEX('2026-실적-MC'!$T:$AQ,ROW('실적-MC 2026'!$B16),MATCH($J$2,'2026-실적-MC'!$T$1:$AQ$1,0)) -> 0 | F16: =+IFERROR(E16/$E$7,0) -> 0 | G16: =+INDEX('2026-사업계획-MC'!$T:$AQ,ROW('실적-MC 2026'!$B16),MATCH($J$1,'2026-사업계획-MC'!$T$1:$AQ$1,0)) -> 0 | H16: =+IFERROR(G16/$G$7,0) -> 0 | I16: =+INDEX('2026-운영계획-MC'!$T:$AQ,ROW('실적-MC 2026'!$B16),MATCH($J$1,'2026-운영계획-MC'!$T$1:$AQ$1,0)) -> 0 | J16: =+IFERROR(I16/$I$7,0) -> 0 | K16: =+INDEX('2026-실적-MC'!$O:$AL,ROW('실적-MC 2026'!$B16),MATCH($J$1,'2026-실적-MC'!$O$1:$AL$1,0)) -> 0 | L16: =+IFERROR(K16/$K$7,0) -> 0 | M16: =IF(G16=0,"",K16/G16) | N16: =IF(I16=0,"",K16/I16) | P16: =K16-G16 -> 0 | Q16: =L16-H16 -> 0 | R16: =K16-I16 -> 0 | S16: =L16-J16 -> 0
B17: 04.잡급 | C17: =+INDEX(#REF!,ROW('실적-MC 2026'!$B17),MATCH('실적-MC 2026'!$J$1,#REF!,0)) -> #REF! | D17: =+IFERROR(C17/$C$7,0) -> 0 | E17: =+INDEX('2026-실적-MC'!$T:$AQ,ROW('실적-MC 2026'!$B17),MATCH($J$2,'2026-실적-MC'!$T$1:$AQ$1,0)) -> 0 | F17: =+IFERROR(E17/$E$7,0) -> 0 | G17: =+INDEX('2026-사업계획-MC'!$T:$AQ,ROW('실적-MC 2026'!$B17),MATCH($J$1,'2026-사업계획-MC'!$T$1:$AQ$1,0)) -> 0 | H17: =+IFERROR(G17/$G$7,0) -> 0 | I17: =+INDEX('2026-운영계획-MC'!$T:$AQ,ROW('실적-MC 2026'!$B17),MATCH($J$1,'2026-운영계획-MC'!$T$1:$AQ$1,0)) -> 0 | J17: =+IFERROR(I17/$I$7,0) -> 0 | K17: =+INDEX('2026-실적-MC'!$O:$AL,ROW('실적-MC 2026'!$B17),MATCH($J$1,'2026-실적-MC'!$O$1:$AL$1,0)) -> 0 | L17: =+IFERROR(K17/$K$7,0) -> 0 | M17: =IF(G17=0,"",K17/G17) | N17: =IF(I17=0,"",K17/I17) | P17: =K17-G17 -> 0 | Q17: =L17-H17 -> 0 | R17: =K17-I17 -> 0 | S17: =L17-J17 -> 0
B18: 05.조립비 | C18: =+INDEX(#REF!,ROW('실적-MC 2026'!$B18),MATCH('실적-MC 2026'!$J$1,#REF!,0)) -> #REF! | D18: =+IFERROR(C18/$C$7,0) -> 0 | E18: =+INDEX('2026-실적-MC'!$T:$AQ,ROW('실적-MC 2026'!$B18),MATCH($J$2,'2026-실적-MC'!$T$1:$AQ$1,0)) -> 0 | F18: =+IFERROR(E18/$E$7,0) -> 0 | G18: =+INDEX('2026-사업계획-MC'!$T:$AQ,ROW('실적-MC 2026'!$B18),MATCH($J$1,'2026-사업계획-MC'!$T$1:$AQ$1,0)) -> 0 | H18: =+IFERROR(G18/$G$7,0) -> 0 | I18: =+INDEX('2026-운영계획-MC'!$T:$AQ,ROW('실적-MC 2026'!$B18),MATCH($J$1,'2026-운영계획-MC'!$T$1:$AQ$1,0)) -> 0 | J18: =+IFERROR(I18/$I$7,0) -> 0 | K18: =+INDEX('2026-실적-MC'!$O:$AL,ROW('실적-MC 2026'!$B18),MATCH($J$1,'2026-실적-MC'!$O$1:$AL$1,0)) -> 0 | L18: =+IFERROR(K18/$K$7,0) -> 0 | M18: =IF(G18=0,"",K18/G18) | N18: =IF(I18=0,"",K18/I18) | P18: =K18-G18 -> 0 | Q18: =L18-H18 -> 0 | R18: =K18-I18 -> 0 | S18: =L18-J18 -> 0
B19: Ⅲ. 경비 | C19: =+INDEX(#REF!,ROW('실적-MC 2026'!$B19),MATCH('실적-MC 2026'!$J$1,#REF!,0)) -> #REF! | D19: =+IFERROR(C19/$C$7,0) -> 0 | E19: =+INDEX('2026-실적-MC'!$T:$AQ,ROW('실적-MC 2026'!$B19),MATCH($J$2,'2026-실적-MC'!$T$1:$AQ$1,0)) -> 0 | F19: =+IFERROR(E19/$E$7,0) -> 0 | G19: =+INDEX('2026-사업계획-MC'!$T:$AQ,ROW('실적-MC 2026'!$B19),MATCH($J$1,'2026-사업계획-MC'!$T$1:$AQ$1,0)) -> 9.4081368e+09 | H19: =+IFERROR(G19/$G$7,0) -> 0.059358755 | I19: =+INDEX('2026-운영계획-MC'!$T:$AQ,ROW('실적-MC 2026'!$B19),MATCH($J$1,'2026-운영계획-MC'!$T$1:$AQ$1,0)) -> 1.0281987e+10 | J19: =+IFERROR(I19/$I$7,0) -> 0.053153002 | K19: =+INDEX('2026-실적-MC'!$O:$AL,ROW('실적-MC 2026'!$B19),MATCH($J$1,'2026-실적-MC'!$O$1:$AL$1,0)) -> 0 | L19: =+IFERROR(K19/$K$7,0) -> 0 | M19: =IF(G19=0,"",K19/G19) -> 0 | N19: =IF(I19=0,"",K19/I19) -> 0 | P19: =K19-G19 -> -9.4081368e+09 | Q19: =L19-H19 -> -0.059358755 | R19: =K19-I19 -> -1.0281987e+10 | S19: =L19-J19 -> -0.053153002
B20: 01.복리후생비 | C20: =+INDEX(#REF!,ROW('실적-MC 2026'!$B20),MATCH('실적-MC 2026'!$J$1,#REF!,0)) -> #REF! | D20: =+IFERROR(C20/$C$7,0) -> 0 | E20: =+INDEX('2026-실적-MC'!$T:$AQ,ROW('실적-MC 2026'!$B20),MATCH($J$2,'2026-실적-MC'!$T$1:$AQ$1,0)) -> 0 | F20: =+IFERROR(E20/$E$7,0) -> 0 | G20: =+INDEX('2026-사업계획-MC'!$T:$AQ,ROW('실적-MC 2026'!$B20),MATCH($J$1,'2026-사업계획-MC'!$T$1:$AQ$1,0)) -> 999328460 | H20: =+IFERROR(G20/$G$7,0) -> 0.0063050628 | I20: =+INDEX('2026-운영계획-MC'!$T:$AQ,ROW('실적-MC 2026'!$B20),MATCH($J$1,'2026-운영계획-MC'!$T$1:$AQ$1,0)) -> 1199194152 | J20: =+IFERROR(I20/$I$7,0) -> 0.0061992655 | K20: =+INDEX('2026-실적-MC'!$O:$AL,ROW('실적-MC 2026'!$B20),MATCH($J$1,'2026-실적-MC'!$O$1:$AL$1,0)) -> 0 | L20: =+IFERROR(K20/$K$7,0) -> 0 | M20: =IF(G20=0,"",K20/G20) -> 0 | N20: =IF(I20=0,"",K20/I20) -> 0 | P20: =K20-G20 -> -999328460 | Q20: =L20-H20 -> -0.0063050628 | R20: =K20-I20 -> -1199194152 | S20: =L20-J20 -> -0.0061992655
B21: 02.여비교통비 | C21: =+INDEX(#REF!,ROW('실적-MC 2026'!$B21),MATCH('실적-MC 2026'!$J$1,#REF!,0)) -> #REF! | D21: =+IFERROR(C21/$C$7,0) -> 0 | E21: =+INDEX('2026-실적-MC'!$T:$AQ,ROW('실적-MC 2026'!$B21),MATCH($J$2,'2026-실적-MC'!$T$1:$AQ$1,0)) -> 0 | F21: =+IFERROR(E21/$E$7,0) -> 0 | G21: =+INDEX('2026-사업계획-MC'!$T:$AQ,ROW('실적-MC 2026'!$B21),MATCH($J$1,'2026-사업계획-MC'!$T$1:$AQ$1,0)) -> 0 | H21: =+IFERROR(G21/$G$7,0) -> 0 | I21: =+INDEX('2026-운영계획-MC'!$T:$AQ,ROW('실적-MC 2026'!$B21),MATCH($J$1,'2026-운영계획-MC'!$T$1:$AQ$1,0)) -> 0 | J21: =+IFERROR(I21/$I$7,0) -> 0 | K21: =+INDEX('2026-실적-MC'!$O:$AL,ROW('실적-MC 2026'!$B21),MATCH($J$1,'2026-실적-MC'!$O$1:$AL$1,0)) -> 0 | L21: =+IFERROR(K21/$K$7,0) -> 0 | M21: =IF(G21=0,"",K21/G21) | N21: =IF(I21=0,"",K21/I21) | P21: =K21-G21 -> 0 | Q21: =L21-H21 -> 0 | R21: =K21-I21 -> 0 | S21: =L21-J21 -> 0
